Workbook

Sheet     2024학년도 입결 분석    
F1: 2024학년도 정시 입결 (70% 컷) 분석 24. 9. 7 | AH1: 제작 및 검토 < 베텔기우스 > | BA1: =IF(E6="","-",E6) -> -
BA2: =IF(E7="","-",E7) -> -
AH3: Betelgeuse058.tistory.com
N4: 1. 본 자료는, 24학년도 정시 입결(대학별 환산점수)을 → '24학년도 수능'의 표준점수와 백분위로 역환산한 산출내역입니다. | BA4: =IF(E8="","-",E8) -> -
E5: 대학명 강조 | F5: 학과명 강조 | N5: (대학별 환산점수는 각 대학에서 공식 발표한 70%컷 입시결과입니다.) | BA5: =IF(F6="","-",F6) -> -
D6: 1 | N6: 2. 모든 학과의 역환산 산출내역(표점입결, 백분위입결)은, 각 대학의 환산공식에 따라 역으로 계산된 자동산출 결과이며, 이는 올해의 원점수 표준점수 백분위점수로 변환 후 예상입결을 산출하는데 사용됩니다. | BA6: =IF(F7="","-",F7) -> -
D7: 2 | N7: 3. 국.수.탐 백분위가 동일할때의 역환산 결과이며, 과목별 반영비율에 따른 유불리는 '환산점수 배치표 탭'을 참고 바랍니다. | BA7: =IF(F8="","-",F8) -> -
D8: 3 | N8: 4. 실제 입시결과이므로, 일부 학과는 적정한 위치보다 높거나 낮은곳에 위치할 수 있습니다 | AZ8: .
AL9: 의대 증원에 따른 입결변화 예측
M10: 입시결과 역환산 산출내역
B11: 자연 누적 (추정치) | D11: 의대증원 | E11: 입시결과 | I11: 대학 | J11: 학과 | K11: 계열 | L11: 모집인원 | M11: 대학별 | O11: 반영방법 | R11: 반영비율 | U11: 백분위 | V11: 표준점수 | Y11: 변표 | Z11: 등급 점수 | AF11: 가산점 | AH11: 비고 | AN11: 증원 | AO11: 증가인원(누적) | AR11: 누적 백분율 변화
D12: 영향 | E12: 자연→인문 | F12: 계열 | G12: 계열 | M12: 환산점수 / | N12: 만점 | O12: 국.수 | P12: 탐구 | R12: 국 | S12: 수 | T12: 탐 | U12: 국.수.탐 | V12: 국어 | W12: 수학 | X12: 탐구 | Y12: 탐구 | Z12: 영어 | AA12: 점수 | AB12: 한국사 | AC12: 점수 | AD12: 제2외국 | AE12: 점수 | AF12: 미기,과탐 | AN12: 영향력 | AO12: 정시모집+수시합격 예상인원 | AR12: (추정치)
B13: (%) | C13: (명) | D13: (명) | E13: 교차표점 | F13: 백분위 | G13: 표준점수 | AG13: 교과 | AN13: (%) | AO13: 자연+인문 | AP13: 자연 | AQ13: 인문 | BA13: 계열ID
B14: 0.01 | C14: 22 | D14: 0 | F14: 99.99 | G14: 431.00 | I14: 서울대 | J14: 의예 | K14: 자연 | L14: 29 | M14: 435.8 / | N14: 600 | O14: 표점 | P14: 표점 | Q14: 2과목 | R14: 33 | S14: 40 | T14: 27 | U14: 99.99 | V14: 147.00544 | W14: 146.50272 | X14: 68.745917 | Z14: 1등급 | AA14: 0 | AB14: 만점 | AC14: 0 | AD14: 만점 | AE14: 0 | AF14: 3 | AG14: 0 | AH14: 과탐Ⅱ3점 가산 | AL14: 서울대 의예 | AM14: 자연 | AN14: 100 | AO14: 0 | AP14: 0 | AQ14: 0 | AR14: 0.03 → 0.03 | BA14: 자연1
B15: 0.24 | C15: 521 | D15: 0 | F15: 99.77 | G15: 425.84 | I15: 가톨릭대 | J15: 의예 | K15: 자연 | L15: 37 | M15: 749.63 / | N15: 1000 | O15: 표점 | P15: 변표 | Q15: 2과목 | R15: 30 | S15: 40 | T15: 30 | U15: 99.77 | V15: 143.68591 | W15: 144.68591 | X15: 68.734094 | Y15: 71.58 | Z15: 1등급 | AA15: 20 | AB15: 만점 | AC15: 10 | AD15: 만점 | AE15: 0 | AF15: 0 | AG15: 0 | AL15: 가톨릭대 의예 | AM15: 자연 | AN15: 100 | AO15: 0 | AP15: 0 | AQ15: 0 | AR15: 0.24 → 0.24 | BA15: 자연2
B16: 0.25 | C16: 543 | D16: 0 | F16: 99.76 | G16: 425.67 | I16: 성균관대 | J16: 의예 | K16: 자연 | L16: 10 | M16: 713.83 / | N16: 1000 | O16: 표점 | P16: 변표 | Q16: 2과목 | R16: 30 | S16: 35 | T16: 25 | U16: 99.76 | V16: 143.60154 | W16: 144.60154 | X16: 68.733462 | Y16: 71.75 | Z16: 1등급 | AA16: 66 | AB16: 만점 | AC16: 0 | AD16: 만점 | AE16: 0 | AF16: 0 | AG16: 0 | AH16: 영어2등급 까지 만점 | AL16: 성균관대 의예 | AM16: 자연 | AN16: 100 | AO16: 0 | AP16: 0 | AQ16: 0 | AR16: 0.25 → 0.25 | BA16: 자연3
B17: 0.26 | C17: 564 | D17: 0 | F17: 99.74 | G17: 425.32 | I17: 연세대 | J17: 의예 | K17: 자연 | L17: 47 | M17: 677.475 / | N17: 900 | O17: 표점 | P17: 변표 | Q17: 2과목 | R17: 22 | S17: 33 | T17: 33 | U17: 99.74 | V17: 143.42634 | W17: 144.42634 | X17: 68.733663 | Y17: 69.14 | Z17: 1등급 | AA17: 100 | AB17: 만점 | AC17: 10 | AD17: 만점 | AE17: 0 | AF17: 0 | AG17: 0 | AL17: 연세대 의예 | AM17: 자연 | AN17: 100 | AO17: 0 | AP17: 0 | AQ17: 0 | AR17: 0.27 → 0.27 | BA17: 자연4
B18: 0.33 | C18: 716 | D18: 0 | F18: 99.67 | G18: 423.85 | I18: 울산대 | J18: 의예 | K18: 자연 | L18: 11 | M18: 980.99 / | N18: 1000 | O18: 표점/만점 | P18: 표점/만점 | Q18: 2과목 | R18: 20 | S18: 30 | T18: 30 | U18: 99.67 | V18: 142.69305 | W18: 143.69305 | X18: 68.731946 | Z18: 1등급 | AA18: 190 | AB18: 만점 | AC18: 10 | AD18: 만점 | AE18: 0 | AF18: 0 | AG18: 0 | AL18: 울산대 의예 | AM18: 자연 | AN18: 100 | AO18: 0 | AP18: 0 | AQ18: 0 | AR18: 0.34 → 0.34 | BA18: 자연5
B19: 0.37 | C19: 803 | D19: 0 | F19: 99.63 | G19: 423.14 | I19: 고려대 | J19: 의예 | K19: 자연 | L19: 27 | M19: 724.53 / | N19: 1000 | O19: 표점 | P19: 변표 | Q19: 2과목 | R19: 31 | S19: 38 | T19: 31 | U19: 99.63 | V19: 142.34009 | W19: 143.34009 | X19: 68.729915 | Y19: 71.48 | Z19: 1등급 | AA19: 0 | AB19: 만점 | AC19: 10 | AD19: 만점 | AE19: 0 | AF19: 0 | AG19: 0 | AL19: 고려대 의예 | AM19: 자연 | AN19: 100 | AO19: 0 | AP19: 0 | AQ19: 0 | AR19: 0.38 → 0.38 | BA19: 자연6
B20: 0.38 | C20: 825 | D20: 0 | F20: 99.62 | G20: 422.94 | I20: 서울대 | J20: 치의학 | K20: 자연 | L20: 10 | M20: 427.1 / | N20: 600 | O20: 표점 | P20: 표점 | Q20: 2과목 | R20: 33 | S20: 40 | T20: 27 | U20: 99.62 | V20: 142.23979 | W20: 143.23979 | X20: 68.730215 | Z20: 1등급 | AA20: 0 | AB20: 만점 | AC20: 0 | AD20: 만점 | AE20: 0 | AF20: 3 | AG20: 0 | AH20: 과탐Ⅱ3점 가산 | AL20: 서울대 치의학 | AM20: 자연 | AN20: 100 | AO20: 0 | AP20: 0 | AQ20: 0 | AR20: 0.39 → 0.39 | BA20: 자연7
B21: 0.55 | C21: 1,194 | D21: 0 | F21: 99.49 | G21: 421.06 | I21: 한양대 | J21: 의예 | K21: 자연 | L21: 68 | M21: 974.45 / | N21: 1000 | O21: 표점/만점 | P21: 변표/만점 | Q21: 2과목 | R21: 20 | S21: 35 | T21: 35 | U21: 99.49 | V21: 141.63418 | W21: 141.96752 | X21: 68.729151 | Y21: 68.83 | Z21: 1등급 | AA21: 100 | AB21: 만점 | AC21: 0 | AD21: 만점 | AE21: 0 | AF21: 0 | AG21: 0 | AL21: 한양대 의예 | AM21: 자연 | AN21: 100 | AO21: 0 | AP21: 0 | AQ21: 0 | AR21: 0.56 → 0.56 | BA21: 자연8
B22: 0.56 | C22: 1,215 | D22: 0 | F22: 99.44 | G22: 420.74 | I22: 경희대 | J22: 의예 | K22: 자연 | L22: 44 | M22: 600.8 / | N22: 800 | O22: 표점 | P22: 변표 | Q22: 2과목 | R22: 20 | S22: 35 | T22: 30 | U22: 99.44 | V22: 141.47606 | W22: 141.8094 | X22: 68.727271 | Y22: 70.45 | Z22: 1등급 | AA22: 120 | AB22: 만점 | AC22: 0 | AD22: 만점 | AE22: 0 | AF22: 0 | AG22: 0 | AL22: 경희대 의예 | AM22: 자연 | AN22: 100 | AO22: 0 | AP22: 0 | AQ22: 0 | AR22: 0.57 → 0.57 | BA22: 자연9
B23: 0.61 | C23: 1,324 | D23: 61 | F23: 99.29 | G23: 419.72 | I23: 아주대 | J23: 의예 | K23: 자연 | L23: 10 | M23: 968.09 / | N23: 1000 | O23: 표점/만점 | P23: 변표/만점 | Q23: 2과목 | R23: 20 | S23: 40 | T23: 30 | U23: 99.29 | V23: 140.96407 | W23: 141.30938 | X23: 68.723276 | Y23: 71.12 | Z23: 1등급 | AA23: 100 | AB23: 만점 | AC23: 0 | AD23: 만점 | AE23: 0 | AF23: 0 | AG23: 0 | AL23: 아주대 의예 | AM23: 자연 | AN23: 100 | AO23: 61 | AP23: 61 | AQ23: 0 | AR23: 0.61 → 0.64 | BA23: 자연10
B24: 0.65 | C24: 1,411 | D24: 18 | F24: 99.24 | G24: 419.26 | I24: 중앙대 | J24: 의학 | K24: 자연 | L24: 45 | M24: 817.23 / | N24: 1000 | O24: 표점 | P24: 변표 | Q24: 2과목 | R24: 25 | S24: 40 | T24: 35 | U24: 99.24 | V24: 140.6866 | W24: 141.1244 | X24: 68.724504 | Y24: 71.18 | Z24: 1등급 | AA24: 100 | AB24: 만점 | AC24: 10 | AD24: 만점 | AE24: 0 | AF24: 0 | AG24: 0 | AL24: 중앙대 의학 | AM24: 자연 | AN24: 30% | AO24: 18 | AP24: 18 | AQ24: 0 | AR24: 0.65 → 0.66 | BA24: 자연11
B25: 0.69 | C25: 1,497 | D25: 71 | F25: 99.18 | G25: 418.79 | I25: 한림대 | J25: 의예 | K25: 자연 | L25: 37 | M25: 967.54 / | N25: 1000 | O25: 표점/만점 | P25: 표점/만점 | Q25: 2과목 | R25: 20 | S25: 40 | T25: 30 | U25: 99.18 | V25: 140.4239 | W25: 140.94926 | X25: 68.70842 | Z25: 1등급 | AA25: 100 | AB25: 만점 | AC25: 0 | AD25: 만점 | AE25: 0 | AF25: 0 | AG25: 0 | AL25: 한림대 의예 | AM25: 자연 | AN25: 100 | AO25: 71 | AP25: 71 | AQ25: 0 | AR25: 0.69 → 0.72 | BA25: 자연12
B26: 0.77 | C26: 1,671 | D26: 363 | F26: 99.04 | G26: 417.39 | I26: 충남대 | J26: 의예 | K26: 자연 | L26: 13 | M26: 208.95 / | N26: 300 | O26: 표점 | P26: 표점 | Q26: 2과목 | R26: 25 | S26: 45 | T26: 30 | U26: 99.04 | V26: 139.69244 | W26: 140.46163 | X26: 68.617968 | Z26: 1등급 | AA26: 0 | AB26: 만점 | AC26: 0 | AD26: 만점 | AE26: 0 | AF26: 0 | AG26: 0 | AL26: 충남대 의예 | AM26: 자연 | AN26: 100 | AO26: 363 | AP26: 363 | AQ26: 0 | AR26: 0.78 → 0.94 | BA26: 자연13
B27: 0.78 | C27: 1,693 | D27: 485 | F27: 99.02 | G27: 417.23 | I27: 인하대 | J27: 의예 | K27: 자연 | L27: 16 | M27: 966.4 / | N27: 1000 | O27: 표점/만점 | P27: 변표/만점 | Q27: 2과목 | R27: 20 | S27: 30 | T27: 25 | U27: 99.02 | V27: 139.61231 | W27: 140.40821 | X27: 68.604738 | Y27: 71.03 | Z27: 1등급 | AA27: 200 | AB27: 만점 | AC27: 50 | AD27: 만점 | AE27: 0 | AF27: 0 | AG27: 0 | AL27: 인하대 의예 | AM27: 자연 | AN27: 100 | AO27: 485 | AP27: 485 | AQ27: 0 | AR27: 0.79 → 1.01 | BA27: 자연14
B28: 0.80 | C28: 1,736 | D28: 485 | F28: 99.00 | G28: 417.02 | I28: 가천대 | J28: 의예 | K28: 자연 | L28: 15 | M28: 98.8 / | N28: 100 | O28: 백분위 | P28: 백분위 | Q28: 2과목 | R28: 25 | S28: 30 | T28: 25 | U28: 99.00 | V28: 139.5 | W28: 140.33333 | X28: 68.593333 | Z28: 1등급 | AA28: 19.6 | AB28: 만점 | AC28: 0 | AD28: 만점 | AE28: 0 | AF28: 0 | AG28: 0 | AL28: 가천대 의예 | AM28: 자연 | AN28: 100 | AO28: 485 | AP28: 485 | AQ28: 0 | AR28: 0.80 → 1.02 | BA28: 자연15
B29: 0.81 | C29: 1,758 | D29: 485 | F29: 98.98 | G29: 416.80 | I29: 부산대 | J29: 의예 | K29: 자연 | L29: 25 | M29: 765.5 / | N29: 1000 | O29: 표점 | P29: 표점 | Q29: 2과목 | R29: 20 | S29: 30 | T29: 30 | U29: 98.98 | V29: 139.38741 | W29: 140.25827 | X29: 68.57716 | Z29: 1등급 | AA29: 200 | AB29: 만점 | AC29: 10 | AD29: 만점 | AE29: 0 | AF29: 0 | AG29: 0 | AL29: 부산대 의예 | AM29: 자연 | AN29: 100 | AO29: 485 | AP29: 485 | AQ29: 0 | AR29: 0.81 → 1.03 | BA29: 자연16
B30: 0.81 | C30: 1,758 | D30: 364 | F30: 98.96 | G30: 416.59 | I30: 서울대 | J30: 수리과학 | K30: 자연 | L30: 10 | M30: 420.2 / | N30: 600 | O30: 표점 | P30: 표점 | Q30: 2과목 | R30: 33 | S30: 40 | T30: 27 | U30: 98.96 | V30: 139.27928 | W30: 140.18619 | X30: 68.562266 | Z30: 1등급 | AA30: 0 | AB30: 만점 | AC30: 0 | AD30: 만점 | AE30: 0 | AF30: 3 | AG30: 0 | AH30: 과탐Ⅱ3점 가산 | AL30: 서울대 수리과학 | AM30: 자연 | AN30: 75% | AO30: 364 | AP30: 364 | AQ30: 0 | AR30: 0.82 → 0.99 | BA30: 자연17
B31: 0.82 | C31: 1,779 | D31: 485 | F31: 98.94 | G31: 416.43 | I31: 이화여대 | J31: 의예 | K31: 자연 | L31: 55 | M31: 973.2 / | N31: 1000 | O31: 표점/만점 | P31: 변표/만점 | Q31: 2과목 | R31: 25 | S31: 30 | T31: 25 | U31: 98.94 | V31: 139.19824 | W31: 140.13216 | X31: 68.549796 | Y31: 70.94 | Z31: 1등급 | AA31: 200 | AB31: 만점 | AC31: 10 | AD31: 만점 | AE31: 0 | AF31: 0 | AG31: 0 | AL31: 이화여대 의예 | AM31: 자연 | AN31: 100 | AO31: 485 | AP31: 485 | AQ31: 0 | AR31: 0.83 → 1.05 | BA31: 자연18
B32: 0.82 | C32: 1,779 | D32: 485 | F32: 98.92 | G32: 416.24 | I32: 경북대 | J32: 의예 | K32: 자연 | L32: 22 | M32: 748.75 / | N32: 1000 | O32: 표점 | P32: 변표 | Q32: 2과목 | R32: 25 | S32: 38 | T32: 25 | U32: 98.92 | V32: 139.1 | W32: 140.06667 | X32: 68.536667 | Y32: 70.9 | Z32: 1등급 | AA32: 125 | AB32: 만점 | AC32: 10 | AD32: 만점 | AE32: 0 | AF32: 0 | AG32: 0 | AL32: 경북대 의예 | AM32: 자연 | AN32: 100 | AO32: 485 | AP32: 485 | AQ32: 0 | AR32: 0.83 → 1.05 | BA32: 자연19
B33: 0.83 | C33: 1,801 | D33: 364 | F33: 98.92 | G33: 416.20 | I33: 서울대 | J33: 약학 | K33: 자연 | L33: 10 | M33: 419.8 / | N33: 600 | O33: 표점 | P33: 표점 | Q33: 2과목 | R33: 33 | S33: 40 | T33: 27 | U33: 98.92 | V33: 139.08036 | W33: 140.05358 | X33: 68.533031 | Z33: 1등급 | AA33: 0 | AB33: 만점 | AC33: 0 | AD33: 만점 | AE33: 0 | AF33: 3 | AG33: 0 | AH33: 과탐Ⅱ3점 가산 | AL33: 서울대 약학 | AM33: 자연 | AN33: 75% | AO33: 364 | AP33: 364 | AQ33: 0 | AR33: 0.84 → 1.00 | BA33: 자연20
B34: 0.83 | C34: 1,801 | D34: 146 | F34: 98.90 | G34: 416.00 | I34: 인제대 | J34: 의예 | K34: 자연 | L34: 22 | M34: 551 / | N34: 800 | O34: 표점 | P34: 표점 | Q34: 2과목 | R34: 25 | S34: 25 | T34: 25 | U34: 98.90 | V34: 138.98342 | W34: 139.97513 | X34: 68.520723 | Z34: 1등급 | AA34: 135 | AB34: 만점 | AC34: 0 | AD34: 만점 | AE34: 0 | AF34: 0 | AG34: 0 | AL34: 인제대 의예 | AM34: 자연 | AN34: 30% | AO34: 146 | AP34: 146 | AQ34: 0 | AR34: 0.84 → 0.91 | BA34: 자연21
B35: 0.86 | C35: 1,866 | D35: 243 | F35: 98.84 | G35: 415.42 | I35: 연세대 | J35: 치의예 | K35: 자연 | L35: 26 | M35: 736.083 / | N35: 1000 | O35: 표점 | P35: 변표 | Q35: 2과목 | R35: 22 | S35: 33 | T35: 33 | U35: 98.84 | V35: 138.78341 | W35: 139.67511 | X35: 68.480742 | Y35: 68.4 | Z35: 1등급 | AA35: 111.11 | AB35: 만점 | AC35: 10 | AD35: 만점 | AE35: 0 | AF35: 0 | AG35: 0 | AL35: 연세대 치의예 | AM35: 자연 | AN35: 50% | AO35: 243 | AP35: 243 | AQ35: 0 | AR35: 0.87 → 0.98 | BA35: 자연22
B36: 0.96 | C36: 2,083 | D36: 153 | F36: 98.73 | G36: 414.38 | I36: 순천향대 | J36: 의예 | K36: 자연 | L36: 27 | M36: 1005.7 / | N36: 200 | O36: 백분위 | P36: 백분위 | Q36: 2과목 | R36: 20 | S36: 30 | T36: 20 | U36: 98.73 | V36: 138.44444 | W36: 139.16667 | X36: 68.384444 | Z36: 1등급 | AA36: 57.6 | AB36: 만점 | AC36: 0 | AD36: 만점 | AE36: 0 | AF36: 9.873 | AG36: 0 | AH36: 미/기/과탐 10%가산 | AL36: 순천향대 의예 | AM36: 자연 | AN36: 30% | AO36: 153 | AP36: 153 | AQ36: 0 | AR36: 0.97 → 1.04 | BA36: 자연23
B37: 0.96 | C37: 2,083 | D37: 307 | F37: 98.73 | G37: 414.35 | I37: 경희대 | J37: 치의예 | K37: 자연 | L37: 33 | M37: 591.47 / | N37: 800 | O37: 표점 | P37: 변표 | Q37: 2과목 | R37: 20 | S37: 35 | T37: 30 | U37: 98.73 | V37: 138.43291 | W37: 139.14936 | X37: 68.383865 | Y37: 69.14 | Z37: 1등급 | AA37: 120 | AB37: 만점 | AC37: 0 | AD37: 만점 | AE37: 0 | AF37: 0 | AG37: 0 | AL37: 경희대 치의예 | AM37: 자연 | AN37: 60% | AO37: 307 | AP37: 307 | AQ37: 0 | AR37: 0.97 → 1.11 | BA37: 자연24
B38: 0.98 | C38: 2,127 | D38: 511 | F38: 98.72 | G38: 414.20 | I38: 경희대 | J38: 한의예(자연) | K38: 자연 | L38: 32 | M38: 591.27 / | N38: 800 | O38: 표점 | P38: 변표 | Q38: 2과목 | R38: 20 | S38: 35 | T38: 30 | U38: 98.72 | V38: 138.38533 | W38: 139.07799 | X38: 68.368343 | Y38: 69.12 | Z38: 1등급 | AA38: 120 | AB38: 만점 | AC38: 0 | AD38: 만점 | AE38: 0 | AF38: 0 | AG38: 0 | AL38: 경희대 한의예(자연) | AM38: 자연 | AN38: 100 | AO38: 511 | AP38: 511 | AQ38: 0 | AR38: 0.99 → 1.22 | BA38: 자연25
B39: 0.99 | C39: 2,148 | D39: 511 | F39: 98.71 | G39: 414.11 | I39: 대구가톨릭대 | J39: 의예 | K39: 자연 | L39: 10 | M39: 557.15 / | N39: 800 | O39: 표점 | P39: 표점/만점 | Q39: 2과목 | R39: 30 | S39: 30 | T39: 13 | U39: 98.71 | V39: 138.3583 | W39: 139.03746 | X39: 68.357121 | Z39: 1등급 | AA39: 120 | AB39: 만점 | AC39: 5 | AD39: 만점 | AE39: 0 | AF39: 0 | AG39: 0 | AL39: 대구가톨릭대 의예 | AM39: 자연 | AN39: 100 | AO39: 511 | AP39: 511 | AQ39: 0 | AR39: 1.00 → 1.23 | BA39: 자연26
B40: 1.00 | C40: 2,170 | D40: 511 | F40: 98.70 | G40: 414.00 | I40: 동아대 | J40: 의예 | K40: 자연 | L40: 9 | M40: 615 / | N40: 800 | O40: 표점 | P40: 표점 | Q40: 2과목 | R40: 25 | S40: 25 | T40: 25 | U40: 98.70 | V40: 138.32628 | W40: 138.97884 | X40: 68.347438 | Z40: 1등급 | AA40: 200 | AB40: 만점 | AC40: 1 | AD40: 만점 | AE40: 0 | AF40: 0 | AG40: 0 | AL40: 동아대 의예 | AM40: 자연 | AN40: 100 | AO40: 511 | AP40: 511 | AQ40: 0 | AR40: 1.01 → 1.24 | BA40: 자연27
...

Sheet  본인점수 입력 
B1: 환산점수 엑셀배치표 2025학년도 수능 실채점기준 (2024. 12. 08 제작)
B2: 제작 및 검토 < 베텔기우스 > Betelgeuse058.tistory.com
AD3: 응시여부코드 | AE3: (1~2) | AF3: (3~5) | AG3: (6~13) | AI3: (10~13) | AJ3: (14~22) | AL3: 23 | AM3: 24 | AN3: 25
B4: 노란칸에 점수를 입력합니다. (영어, 한국사, 제2외국어 등 응시한 과목은 모두 입력해야 지원가능 여부를 알 수 있습니다.) (미응시 영역은 비워둠) | AE4: 적용점수
AE5: 고득점순 | AF5: 고득점순 | AG5: 고득점순 | AH5: 고득점순 | AI5: 가산점용 | AJ5: 고득점순 | AK5: 고득점순 | AL5: 고득점순 | AM5: 고득점순 | AN5: 고득점순
B6: 국어 | D6: 수학 | G6: 과탐 | O6: 사탐 | AE6: 1 | AF6: 1 | AG6: 1 | AH6: 2 | AI6: 1 | AJ6: 1 | AK6: 2 | AL6: 1 | AM6: 1 | AN6: 1
B7: 언매 | C7: 화작 | D7: 미적 | E7: 기하 | F7: 확통 | G7: 물리Ⅰ | H7: 화학Ⅰ | I7: 생명과학Ⅰ | J7: 지구과학Ⅰ | K7: 물리II | L7: 화학II | M7: 생명과학II | N7: 지구과학II | O7: 생활과윤리 | P7: 윤리와사상 | Q7: 한국지리 | R7: 세계지리 | S7: 동아시아사 | T7: 세계사 | U7: 경제 | V7: 정치와법 | W7: 사회문화 | AE7: 국어 | AF7: 수학 | AG7: 과탐1 | AH7: 과탐2 | AI7: 과탐Ⅱ | AJ7: 사탐1 | AK7: 사탐2 | AL7: 영어 | AM7: 한국사 | AN7: 제2외국어
A8: 원점수 | AD8: 원점 | AE8: =IFERROR(INDEX(B8:C8,MATCH($AE$6,B38:C38,0)),0) -> 0 | AF8: =IFERROR(INDEX(D8:F8,MATCH($AF$6,D38:F38,0)),0) -> 0 | AG8: =IFERROR(INDEX($G8:$N8,MATCH(AG$6,$G$38:$N$38,0)),0) -> 0 | AH8: =IFERROR(INDEX($G8:$N8,MATCH(AH$6,$G$38:$N$38,0)),0) -> 0 | AI8: =IFERROR(MAX(K8:N8),0) -> 0 | AJ8: =IFERROR(INDEX(O8:W8,MATCH($AJ$6,O38:W38,0)),0) -> 0 | AK8: =IFERROR(INDEX(O8:W8,MATCH($AK$6,O38:W38,0)),0) -> 0 | AL8: =B14 -> 0 | AM8: =C14 -> 0 | AN8: =D14 -> 0
A9: 표준점수 | B9: =IF($B$31=1,B22,IFERROR(ROUND(B58,0),"")) -> 0 | C9: =IF($B$31=1,C22,IFERROR(ROUND(C58,0),"")) -> 0 | D9: =IF($B$31=1,D22,IFERROR(ROUND(D58,0),"")) -> 0 | E9: =IF($B$31=1,E22,IFERROR(ROUND(E58,0),"")) -> 0 | F9: =IF($B$31=1,F22,IFERROR(ROUND(F58,0),"")) -> 0 | G9: =IF($B$31=1,G22,IFERROR(ROUND(G58,0),"")) -> 0 | H9: =IF($B$31=1,H22,IFERROR(ROUND(H58,0),"")) -> 0 | I9: =IF($B$31=1,I22,IFERROR(ROUND(I58,0),"")) -> 0 | ... W9: =IF($B$31=1,W22,IFERROR(ROUND(W58,0),"")) -> 0 | AD9: 표점 | AE9: =IFERROR(INDEX(B9:C9,MATCH($AE$6,B39:C39,0)),0) -> 0 | AF9: =IFERROR(INDEX(D9:F9,MATCH($AF$6,D39:F39,0)),0) -> 0 | AG9: =IFERROR(INDEX($G9:$N9,MATCH(AG$6,$G$39:$N$39,0)),0) -> 0 | AH9: =IFERROR(INDEX($G9:$N9,MATCH(AH$6,$G$39:$N$39,0)),0) -> 0 | AI9: =IFERROR(MAX(K9:N9),0) -> 0 | AJ9: =IFERROR(INDEX(O9:W9,MATCH($AJ$6,O39:W39,0)),0) -> 0 | AK9: =IFERROR(INDEX(O9:W9,MATCH($AK$6,O39:W39,0)),0) -> 0 | AL9: =B15 -> 0 | AM9: =C15 -> 0 | AN9: =D15 -> 0
A10: 백분위 | B10: =IF($B$31=1,B23,IF(B58="","",IFERROR(IF(MAX($B$163:$B$178)>110,INDEX($A$163:$A$253,MATCH(B$58,B163:B253,-1)),INDEX(B163:B253,MATCH(B$8,$A$163:$A$253,0))),""))) -> 0 | C10: =IF($B$31=1,C23,IF(C58="","",IFERROR(IF(MAX($B$163:$B$178)>110,INDEX($A$163:$A$253,MATCH(C$58,C163:C253,-1)),INDEX(C163:C253,MATCH(C$8,$A$163:$A$253,0))),""))) -> 0 | D10: =IF($B$31=1,D23,IF(D58="","",IFERROR(IF(MAX($B$163:$B$178)>110,INDEX($A$163:$A$253,MATCH(D$58,D163:D253,-1)),INDEX(D163:D253,MATCH(D$8,$A$163:$A$253,0))),""))) -> 0 | E10: =IF($B$31=1,E23,IF(E58="","",IFERROR(IF(MAX($B$163:$B$178)>110,INDEX($A$163:$A$253,MATCH(E$58,E163:E253,-1)),INDEX(E163:E253,MATCH(E$8,$A$163:$A$253,0))),""))) -> 0 | F10: =IF($B$31=1,F23,IF(F58="","",IFERROR(IF(MAX($B$163:$B$178)>110,INDEX($A$163:$A$253,MATCH(F$58,F163:F253,-1)),INDEX(F163:F253,MATCH(F$8,$A$163:$A$253,0))),""))) -> 0 | G10: =IF($B$31=1,G23,IF(G58="","",IFERROR(IF(MAX($B$163:$B$178)>110,INDEX($A$163:$A$253,MATCH(G$58,G163:G253,-1)),INDEX(G163:G253,MATCH(G$8,$AA$163:$AA$253,0))),""))) -> 0 | H10: =IF($B$31=1,H23,IF(H58="","",IFERROR(IF(MAX($B$163:$B$178)>110,INDEX($A$163:$A$253,MATCH(H$58,H163:H253,-1)),INDEX(H163:H253,MATCH(H$8,$AA$163:$AA$253,0))),""))) -> 0 | I10: =IF($B$31=1,I23,IF(I58="","",IFERROR(IF(MAX($B$163:$B$178)>110,INDEX($A$163:$A$253,MATCH(I$58,I163:I253,-1)),INDEX(I163:I253,MATCH(I$8,$AA$163:$AA$253,0))),""))) -> 0 | J10: =IF($B$31=1,J23,IF(J58="","",IFERROR(IF(MAX($B$163:$B$178)>110,INDEX($A$163:$A$253,MATCH(J$58,J163:J253,-1)),INDEX(J163:J253,MATCH(J$8,$AA$163:$AA$253,0))),""))) -> 0 | K10: =IF($B$31=1,K23,IF(K58="","",IFERROR(IF(MAX($B$163:$B$178)>110,INDEX($A$163:$A$253,MATCH(K$58,K163:K253,-1)),INDEX(K163:K253,MATCH(K$8,$AA$163:$AA$253,0))),""))) -> 0 | L10: =IF($B$31=1,L23,IF(L58="","",IFERROR(IF(MAX($B$163:$B$178)>110,INDEX($A$163:$A$253,MATCH(L$58,L163:L253,-1)),INDEX(L163:L253,MATCH(L$8,$AA$163:$AA$253,0))),""))) -> 0 | M10: =IF($B$31=1,M23,IF(M58="","",IFERROR(IF(MAX($B$163:$B$178)>110,INDEX($A$163:$A$253,MATCH(M$58,M163:M253,-1)),INDEX(M163:M253,MATCH(M$8,$AA$163:$AA$253,0))),""))) -> 0 | N10: =IF($B$31=1,N23,IF(N58="","",IFERROR(IF(MAX($B$163:$B$178)>110,INDEX($A$163:$A$253,MATCH(N$58,N163:N253,-1)),INDEX(N163:N253,MATCH(N$8,$AA$163:$AA$253,0))),""))) -> 0 | ... W10: =IF($B$31=1,W23,IF(W58="","",IFERROR(IF(MAX($B$163:$B$178)>110,INDEX($A$163:$A$253,MATCH(W$58,W163:W253,-1)),INDEX(W163:W253,MATCH(W$8,$AA$163:$AA$253,0))),""))) -> 0 | AD10: 백분 | AE10: =IFERROR(INDEX(B10:C10,MATCH($AE$6,B40:C40,0)),0) -> 0 | AF10: =IFERROR(INDEX(D10:F10,MATCH($AF$6,D40:F40,0)),0) -> 0 | AG10: =IFERROR(INDEX($G10:$N10,MATCH(AG$6,$G$40:$N$40,0)),0) -> 0 | AH10: =IFERROR(INDEX($G10:$N10,MATCH(AH$6,$G$40:$N$40,0)),0) -> 0 | AI10: =IFERROR(MAX(K10:N10),0) -> 0 | AJ10: =IFERROR(INDEX(O10:W10,MATCH($AJ$6,O40:W40,0)),0) -> 0 | AK10: =IFERROR(INDEX(O10:W10,MATCH($AK$6,O40:W40,0)),0) -> 0 | AL10: =B16 -> 0 | AM10: =C16 -> 0 | AN10: =D16 -> 0
A11: 등급 | B11: =IF($B$31=1,B24,IF(B8="","",IFERROR(INDEX(B263:B353,MATCH(B$8,$A$263:$A$353,0)),""))) -> 0 | C11: =IF($B$31=1,C24,IF(C8="","",IFERROR(INDEX(C263:C353,MATCH(C$8,$A$263:$A$353,0)),""))) -> 0 | D11: =IF($B$31=1,D24,IF(D8="","",IFERROR(INDEX(D263:D353,MATCH(D$8,$A$263:$A$353,0)),""))) -> 0 | E11: =IF($B$31=1,E24,IF(E8="","",IFERROR(INDEX(E263:E353,MATCH(E$8,$A$263:$A$353,0)),""))) -> 0 | F11: =IF($B$31=1,F24,IF(F8="","",IFERROR(INDEX(F263:F353,MATCH(F$8,$A$263:$A$353,0)),""))) -> 0 | G11: =IF($B$31=1,G24,IF(G8="","",IFERROR(INDEX(G263:G353,MATCH(G$8,$AA$263:$AA$353,0)),""))) -> 0 | H11: =IF($B$31=1,H24,IF(H8="","",IFERROR(INDEX(H263:H353,MATCH(H$8,$AA$263:$AA$353,0)),""))) -> 0 | I11: =IF($B$31=1,I24,IF(I8="","",IFERROR(INDEX(I263:I353,MATCH(I$8,$AA$263:$AA$353,0)),""))) -> 0 | J11: =IF($B$31=1,J24,IF(J8="","",IFERROR(INDEX(J263:J353,MATCH(J$8,$AA$263:$AA$353,0)),""))) -> 0 | K11: =IF($B$31=1,K24,IF(K8="","",IFERROR(INDEX(K263:K353,MATCH(K$8,$AA$263:$AA$353,0)),""))) -> 0 | L11: =IF($B$31=1,L24,IF(L8="","",IFERROR(INDEX(L263:L353,MATCH(L$8,$AA$263:$AA$353,0)),""))) -> 0 | M11: =IF($B$31=1,M24,IF(M8="","",IFERROR(INDEX(M263:M353,MATCH(M$8,$AA$263:$AA$353,0)),""))) -> 0 | N11: =IF($B$31=1,N24,IF(N8="","",IFERROR(INDEX(N263:N353,MATCH(N$8,$AA$263:$AA$353,0)),""))) -> 0 | ... W11: =IF($B$31=1,W24,IF(W8="","",IFERROR(INDEX(W263:W353,MATCH(W$8,$AA$263:$AA$353,0)),""))) -> 0 | AD11: 등급 | AE11: =IFERROR(INDEX(B11:C11,MATCH($AE$6,B41:C41,0)),0) -> 0 | AF11: =IFERROR(INDEX(D11:F11,MATCH($AF$6,D41:F41,0)),0) -> 0 | AG11: =IFERROR(INDEX($G11:$N11,MATCH(AG$6,$G$41:$N$41,0)),0) -> 0 | AH11: =IFERROR(INDEX($G11:$N11,MATCH(AH$6,$G$41:$N$41,0)),0) -> 0 | AI11: =IFERROR(MAX(K11:N11),0) -> 0 | AJ11: =IFERROR(INDEX(O11:W11,MATCH($AJ$6,O41:W41,0)),0) -> 0 | AK11: =IFERROR(INDEX(O11:W11,MATCH($AK$6,O41:W41,0)),0) -> 0 | AL11: =B17 | AM11: =C17 | AN11: =D17
B13: 영어 | C13: 한국사 | D13: 제2외국어
A14: 원점수
A15: 표준점수
A16: 백분위 | AD16: 변표 | AE16: =IFERROR(INDEX(B21:C21,MATCH($AE$6,B42:C42,0)),0) -> 0 | AF16: =IFERROR(INDEX(D21:F21,MATCH($AF$6,D42:F42,0)),0) -> 0 | AG16: =IFERROR(INDEX($G21:$N21,MATCH(AG$6,$G$42:$N$42,0)),0) -> 0 | AH16: =IFERROR(INDEX($G21:$N21,MATCH(AH$6,$G$42:$N$42,0)),0) -> 0 | AI16: =IFERROR(MAX(K21:N21),0) -> 0 | AJ16: =IFERROR(INDEX(O21:W21,MATCH($AJ$6,O42:W42,0)),0) -> 0 | AK16: =IFERROR(INDEX(O21:W21,MATCH($AK$6,O42:W42,0)),0) -> 0 | AL16: =X21 -> 0 | AM16: =Y21 -> 0 | AN16: =Z21 -> 0
A17: 등급 | B17: =IF(AND(B31=1,B27>0),B27,IF(B14="","",IFERROR(INDEX(X263:X353,MATCH(B$14,$A$263:$A$333,0)),""))) | C17: =IF(AND(B31=1,C27>0),C27,IF(C14="","",IFERROR(INDEX(Y263:Y353,MATCH(C$14,$AA$263:$AA$333,0)),""))) | D17: =IF(AND(C31=1,D27>0),D27,IF(D14="","",IFERROR(INDEX(Z263:Z353,MATCH(D$14,$AA$263:$AA$333,0)),""))) | AD17: 최고표점 | AE17: =IFERROR(MAX(B32:C32),0) -> 139 | AF17: =IFERROR(MAX(D32:F32),0) -> 140 | AG17: =IFERROR(INDEX($G32:$N32,MATCH(AG$6,$G$39:$N$39,0)),0) -> 72 | AH17: =IFERROR(INDEX($G32:$N32,MATCH(AH$6,$G$39:$N$39,0)),0) -> 72 | AI17: =IFERROR(INDEX(K32:N32,MATCH(AI6,K39:N39,0)),0) -> 72 | AJ17: =IFERROR(INDEX(O32:W32,MATCH($AJ$6,O39:W39,0)),0) -> 69 | AK17: =IFERROR(INDEX(O32:W32,MATCH($AK$6,O39:W39,0)),0) -> 66 | AL17: =X22 -> 0 | AM17: =Y22 -> 0 | AN17: =Z22 -> 0
AD18: 응시과목명 | AG18: =IFERROR(INDEX($G7:$N7,MATCH(AG$6,$G$39:$N$39,0)),0) -> 지구과학II | AH18: =IFERROR(INDEX($G7:$N7,MATCH(AH$6,$G$39:$N$39,0)),0) -> 생명과학II | AI18: =IF(K43>0,K7,IF(L43>0,L7,IF(M43>0,M7,IF(N43>0,N7,"미응시")))) -> 미응시
AF19: 과탐 전체최고표점 | AG19: =LARGE(G32:N32,1) -> 73
B20: 국어 | D20: 수학 | G20: 과탐 | O20: 사탐 | AD20: 표점합 | AE20: =B22+C22+D22+F22+E22+G22+H22+I22+J22+K22+L22+M22+N22+O22+P22+Q22+R22+S22+T22+U22+V22+W22 -> 0
B21: 언매 | C21: 화작 | D21: 미적 | E21: 기하 | F21: 확통 | G21: 물리Ⅰ | H21: 화학Ⅰ | I21: 생명과학Ⅰ | J21: 지구과학Ⅰ | K21: 물리II | L21: 화학II | M21: 생명과학II | N21: 지구과학II | O21: 생활과윤리 | P21: 윤리와사상 | Q21: 한국지리 | R21: 세계지리 | S21: 동아시아사 | T21: 세계사 | U21: 경제 | V21: 정치와법 | W21: 사회문화
A22: 표준점수 | AD22: *원점일때 20~27행 축소
A23: 백분위 | AD23: *표점일때 ad~an열은 축소
A24: 등급
B26: 영어 | C26: 한국사 | D26: 제2외국어
A27: 등급
A31: 원점/표점코드 | B31: ='배치점수 계산기'!E4 -> 1 | C31: ='배치점수 계산기'!D5 -> 표준점수 기준 | E31: *코드는 배치점수 계산기의 값을 따름 | X31: 영어 | Y31: 한국사 | Z31: 제2외국
A32: 최고표점 | B32: =IFERROR(IF($B$31=1,B49,ROUND(B63,0)),"") -> 139 | C32: =IFERROR(IF($B$31=1,C49,ROUND(C63,0)),"") -> 139 | D32: =IFERROR(IF($B$31=1,D49,ROUND(D63,0)),"") -> 140 | E32: =IFERROR(IF($B$31=1,E49,ROUND(E63,0)),"") -> 137 | F32: =IFERROR(IF($B$31=1,F49,ROUND(F63,0)),"") -> 134 | G32: =IFERROR(IF($B$31=1,G49,ROUND(G63,0)),"") -> 67 | H32: =IFERROR(IF($B$31=1,H49,ROUND(H63,0)),"") -> 65 | I32: =IFERROR(IF($B$31=1,I49,ROUND(I63,0)),"") -> 70 | ... W32: =IFERROR(IF($B$31=1,W49,ROUND(W63,0)),"") -> 69 | X32: =IFERROR(X63,"") -> 0 | Y32: =IFERROR(Y63,"") -> 0 | Z32: =IFERROR(Z63,"") -> 0
A33: 원점순위용 | B33: =IF(B8="","",B8+COLUMN(B8)*0.0001) | C33: =IF(C8="","",C8+COLUMN(C8)*0.0001) | D33: =IF(D8="","",D8+COLUMN(D8)*0.0001) | E33: =IF(E8="","",E8+COLUMN(E8)*0.0001) | F33: =IF(F8="","",F8+COLUMN(F8)*0.0001) | G33: =IF(G8="","",G8+COLUMN(G8)*0.0001) | H33: =IF(H8="","",H8+COLUMN(H8)*0.0001) | I33: =IF(I8="","",I8+COLUMN(I8)*0.0001) | ... W33: =IF(W8="","",W8+COLUMN(W8)*0.0001)
A34: 표점순위용 | B34: =IFERROR(IF($B$31=9,B9+COLUMN(B9)*0.0001,B22+COLUMN(B22)*0.0001),"") -> 0.0002 | C34: =IFERROR(IF($B$31=9,C9+COLUMN(C9)*0.0001,C22+COLUMN(C22)*0.0001),"") -> 0.0003 | D34: =IFERROR(IF($B$31=9,D9+COLUMN(D9)*0.0001,D22+COLUMN(D22)*0.0001),"") -> 0.0004 | E34: =IFERROR(IF($B$31=9,E9+COLUMN(E9)*0.0001,E22+COLUMN(E22)*0.0001),"") -> 0.0005 | F34: =IFERROR(IF($B$31=9,F9+COLUMN(F9)*0.0001,F22+COLUMN(F22)*0.0001),"") -> 0.0006 | G34: =IFERROR(IF($B$31=9,G9+COLUMN(G9)*0.0001,G22+COLUMN(G22)*0.0001),"") -> 0.0007 | H34: =IFERROR(IF($B$31=9,H9+COLUMN(H9)*0.0001,H22+COLUMN(H22)*0.0001),"") -> 0.0008 | I34: =IFERROR(IF($B$31=9,I9+COLUMN(I9)*0.0001,I22+COLUMN(I22)*0.0001),"") -> 0.0009 | ... W34: =IFERROR(IF($B$31=9,W9+COLUMN(W9)*0.0001,W22+COLUMN(W22)*0.0001),"") -> 0.0023
A35: 백분순위용 | B35: =IFERROR(IF($B$31=9,B10+COLUMN(B10)*0.0001,B23+COLUMN(B23)*0.0001),"") -> 0.0002 | C35: =IFERROR(IF($B$31=9,C10+COLUMN(C10)*0.0001,C23+COLUMN(C23)*0.0001),"") -> 0.0003 | D35: =IFERROR(IF($B$31=9,D10+COLUMN(D10)*0.0001,D23+COLUMN(D23)*0.0001),"") -> 0.0004 | E35: =IFERROR(IF($B$31=9,E10+COLUMN(E10)*0.0001,E23+COLUMN(E23)*0.0001),"") -> 0.0005 | F35: =IFERROR(IF($B$31=9,F10+COLUMN(F10)*0.0001,F23+COLUMN(F23)*0.0001),"") -> 0.0006 | G35: =IFERROR(IF($B$31=9,G10+COLUMN(G10)*0.0001,G23+COLUMN(G23)*0.0001),"") -> 0.0007 | H35: =IFERROR(IF($B$31=9,H10+COLUMN(H10)*0.0001,H23+COLUMN(H23)*0.0001),"") -> 0.0008 | I35: =IFERROR(IF($B$31=9,I10+COLUMN(I10)*0.0001,I23+COLUMN(I23)*0.0001),"") -> 0.0009 | ... W35: =IFERROR(IF($B$31=9,W10+COLUMN(W10)*0.0001,W23+COLUMN(W23)*0.0001),"") -> 0.0023
A36: 등급순위용 | B36: =IFERROR(IF($B$31=9,B11+COLUMN(B11)*0.0001,B24+COLUMN(B24)*0.0001),"") -> 0.0002 | C36: =IFERROR(IF($B$31=9,C11+COLUMN(C11)*0.0001,C24+COLUMN(C24)*0.0001),"") -> 0.0003 | D36: =IFERROR(IF($B$31=9,D11+COLUMN(D11)*0.0001,D24+COLUMN(D24)*0.0001),"") -> 0.0004 | E36: =IFERROR(IF($B$31=9,E11+COLUMN(E11)*0.0001,E24+COLUMN(E24)*0.0001),"") -> 0.0005 | F36: =IFERROR(IF($B$31=9,F11+COLUMN(F11)*0.0001,F24+COLUMN(F24)*0.0001),"") -> 0.0006 | G36: =IFERROR(IF($B$31=9,G11+COLUMN(G11)*0.0001,G24+COLUMN(G24)*0.0001),"") -> 0.0007 | H36: =IFERROR(IF($B$31=9,H11+COLUMN(H11)*0.0001,H24+COLUMN(H24)*0.0001),"") -> 0.0008 | I36: =IFERROR(IF($B$31=9,I11+COLUMN(I11)*0.0001,I24+COLUMN(I24)*0.0001),"") -> 0.0009 | ... W36: =IFERROR(IF($B$31=9,W11+COLUMN(W11)*0.0001,W24+COLUMN(W24)*0.0001),"") -> 0.0023 | X36: =IF($B$31=9,B17+COLUMN(B17)*0.0001,B27+COLUMN(B27)*0.0001) -> 0.0002 | Y36: =IF($B$31=9,C17+COLUMN(C17)*0.0001,C27+COLUMN(C27)*0.0001) -> 0.0003 | Z36: =IF($B$31=9,D17+COLUMN(D17)*0.0001,D27+COLUMN(D27)*0.0001) -> 0.0004
A38: 원점순위 | B38: =IFERROR(RANK(B33,$B33:$C33,0),"") | C38: =IFERROR(RANK(C33,$B33:$C33,0),"") | D38: =IFERROR(RANK(D33,$D33:$F33,0),"") | E38: =IFERROR(RANK(E33,$D33:$F33,0),"") | F38: =IFERROR(RANK(F33,$D33:$F33,0),"") | G38: =IFERROR(RANK(G33,$G33:$N33,0),"") | H38: =IFERROR(RANK(H33,$G33:$N33,0),"") | I38: =IFERROR(RANK(I33,$G33:$N33,0),"") | J38: =IFERROR(RANK(J33,$G33:$N33,0),"") | K38: =IFERROR(RANK(K33,$G33:$N33,0),"") | L38: =IFERROR(RANK(L33,$G33:$N33,0),"") | M38: =IFERROR(RANK(M33,$G33:$N33,0),"") | N38: =IFERROR(RANK(N33,$G33:$N33,0),"") | O38: =IFERROR(RANK(O33,$O33:$W33,0),"") | P38: =IFERROR(RANK(P33,$O33:$W33,0),"") | Q38: =IFERROR(RANK(Q33,$O33:$W33,0),"") | R38: =IFERROR(RANK(R33,$O33:$W33,0),"") | S38: =IFERROR(RANK(S33,$O33:$W33,0),"") | T38: =IFERROR(RANK(T33,$O33:$W33,0),"") | U38: =IFERROR(RANK(U33,$O33:$W33,0),"") | V38: =IFERROR(RANK(V33,$O33:$W33,0),"") | W38: =IFERROR(RANK(W33,$O33:$W33,0),"")
A39: 표점순위 | B39: =IFERROR(RANK(B34,$B34:$C34,0),"") -> 2 | C39: =IFERROR(RANK(C34,$B34:$C34,0),"") -> 1 | D39: =IFERROR(RANK(D34,$D34:$F34,0),"") -> 3 | E39: =IFERROR(RANK(E34,$D34:$F34,0),"") -> 2 | F39: =IFERROR(RANK(F34,$D34:$F34,0),"") -> 1 | G39: =IFERROR(RANK(G34,$G34:$N34,0),"") -> 8 | H39: =IFERROR(RANK(H34,$G34:$N34,0),"") -> 7 | I39: =IFERROR(RANK(I34,$G34:$N34,0),"") -> 6 | J39: =IFERROR(RANK(J34,$G34:$N34,0),"") -> 5 | K39: =IFERROR(RANK(K34,$G34:$N34,0),"") -> 4 | L39: =IFERROR(RANK(L34,$G34:$N34,0),"") -> 3 | M39: =IFERROR(RANK(M34,$G34:$N34,0),"") -> 2 | N39: =IFERROR(RANK(N34,$G34:$N34,0),"") -> 1 | O39: =IFERROR(RANK(O34,$O34:$W34,0),"") -> 9 | P39: =IFERROR(RANK(P34,$O34:$W34,0),"") -> 8 | Q39: =IFERROR(RANK(Q34,$O34:$W34,0),"") -> 7 | R39: =IFERROR(RANK(R34,$O34:$W34,0),"") -> 6 | S39: =IFERROR(RANK(S34,$O34:$W34,0),"") -> 5 | T39: =IFERROR(RANK(T34,$O34:$W34,0),"") -> 4 | U39: =IFERROR(RANK(U34,$O34:$W34,0),"") -> 3 | V39: =IFERROR(RANK(V34,$O34:$W34,0),"") -> 2 | W39: =IFERROR(RANK(W34,$O34:$W34,0),"") -> 1
A40: 백분순위 | B40: =IFERROR(RANK(B35,$B35:$C35,0),"") -> 2 | C40: =IFERROR(RANK(C35,$B35:$C35,0),"") -> 1 | D40: =IFERROR(RANK(D35,$D35:$F35,0),"") -> 3 | E40: =IFERROR(RANK(E35,$D35:$F35,0),"") -> 2 | F40: =IFERROR(RANK(F35,$D35:$F35,0),"") -> 1 | G40: =IFERROR(RANK(G35,$G35:$N35,0),"") -> 8 | H40: =IFERROR(RANK(H35,$G35:$N35,0),"") -> 7 | I40: =IFERROR(RANK(I35,$G35:$N35,0),"") -> 6 | J40: =IFERROR(RANK(J35,$G35:$N35,0),"") -> 5 | K40: =IFERROR(RANK(K35,$G35:$N35,0),"") -> 4 | L40: =IFERROR(RANK(L35,$G35:$N35,0),"") -> 3 | M40: =IFERROR(RANK(M35,$G35:$N35,0),"") -> 2 | N40: =IFERROR(RANK(N35,$G35:$N35,0),"") -> 1 | O40: =IFERROR(RANK(O35,$O35:$W35,0),"") -> 9 | P40: =IFERROR(RANK(P35,$O35:$W35,0),"") -> 8 | Q40: =IFERROR(RANK(Q35,$O35:$W35,0),"") -> 7 | R40: =IFERROR(RANK(R35,$O35:$W35,0),"") -> 6 | S40: =IFERROR(RANK(S35,$O35:$W35,0),"") -> 5 | T40: =IFERROR(RANK(T35,$O35:$W35,0),"") -> 4 | U40: =IFERROR(RANK(U35,$O35:$W35,0),"") -> 3 | V40: =IFERROR(RANK(V35,$O35:$W35,0),"") -> 2 | W40: =IFERROR(RANK(W35,$O35:$W35,0),"") -> 1
A41: 등급순위 | B41: =IFERROR(RANK(B36,$B36:$C36,0),"") -> 2 | C41: =IFERROR(RANK(C36,$B36:$C36,0),"") -> 1 | D41: =IFERROR(RANK(D36,$D36:$F36,0),"") -> 3 | E41: =IFERROR(RANK(E36,$D36:$F36,0),"") -> 2 | F41: =IFERROR(RANK(F36,$D36:$F36,0),"") -> 1 | G41: =IFERROR(RANK(G36,$G36:$N36,0),"") -> 8 | H41: =IFERROR(RANK(H36,$G36:$N36,0),"") -> 7 | I41: =IFERROR(RANK(I36,$G36:$N36,0),"") -> 6 | J41: =IFERROR(RANK(J36,$G36:$N36,0),"") -> 5 | K41: =IFERROR(RANK(K36,$G36:$N36,0),"") -> 4 | L41: =IFERROR(RANK(L36,$G36:$N36,0),"") -> 3 | M41: =IFERROR(RANK(M36,$G36:$N36,0),"") -> 2 | N41: =IFERROR(RANK(N36,$G36:$N36,0),"") -> 1 | O41: =IFERROR(RANK(O36,$O36:$W36,0),"") -> 9 | P41: =IFERROR(RANK(P36,$O36:$W36,0),"") -> 8 | Q41: =IFERROR(RANK(Q36,$O36:$W36,0),"") -> 7 | R41: =IFERROR(RANK(R36,$O36:$W36,0),"") -> 6 | S41: =IFERROR(RANK(S36,$O36:$W36,0),"") -> 5 | T41: =IFERROR(RANK(T36,$O36:$W36,0),"") -> 4 | U41: =IFERROR(RANK(U36,$O36:$W36,0),"") -> 3 | V41: =IFERROR(RANK(V36,$O36:$W36,0),"") -> 2 | W41: =IFERROR(RANK(W36,$O36:$W36,0),"") -> 1
A43: 응시여부 | B43: =IF(OR(B8>0,AND(B22>0,B23>0)),1,0) -> 0 | C43: =IF(OR(C8>0,AND(C22>0,C23>0)),1,0) -> 0 | D43: =IF(OR(D8>0,AND(D22>0,D23>0)),1,0) -> 0 | E43: =IF(OR(E8>0,AND(E22>0,E23>0)),1,0) -> 0 | F43: =IF(OR(F8>0,AND(F22>0,F23>0)),1,0) -> 0 | G43: =IF(OR(G8>0,AND(G22>0,G23>0)),1,0) -> 0 | H43: =IF(OR(H8>0,AND(H22>0,H23>0)),1,0) -> 0 | I43: =IF(OR(I8>0,AND(I22>0,I23>0)),1,0) -> 0 | ... W43: =IF(OR(W8>0,AND(W22>0,W23>0)),1,0) -> 0 | X43: =IF(OR(B14>0,AND(B27>0,B27>0)),1,0) -> 0 | Y43: =IF(OR(C14>0,AND(C27>0,C27>0)),1,0) -> 0 | Z43: =IF(OR(D14>0,AND(D27>0,D27>0)),1,0) -> 0
B47: *'도수분포 파일'로부터 만점표점 붙여넣기(과목순서 유의) | H47: *표점/만점 대비 점수 산출용으로 사용. 표점기준 배치표일경우만 의미있음
B48: 언매 | C48: 화작 | D48: 미적 | E48: 기하 | F48: 확통 | G48: 물리Ⅰ | H48: 화학Ⅰ | I48: 생물Ⅰ | J48: 지구과학Ⅰ | K48: 물리II | L48: 화학II | M48: 생물II | N48: 지구과학II | O48: 생활과윤리 | P48: 윤리와사상 | Q48: 한국지리 | R48: 세계지리 | S48: 동아시아사 | T48: 세계사 | U48: 경제 | V48: 정치와법 | W48: 사회문화 | X48: 과탐전체 | Y48: 사탐전체 | Z48: 탐구전체
A49: 만점표점 | B49: 139 | C49: 139 | D49: 140 | E49: 137 | F49: 134 | G49: 67 | H49: 65 | I49: 70 | J49: 72 | K49: 70 | L49: 73 | M49: 72 | N49: 72 | O49: 77 | P49: 73 | Q49: 69 | R49: 68 | S49: 67 | T49: 68 | U49: 72 | V49: 66 | W49: 69 | X49: 69.823 | Y49: 71.561 | Z49: 70.789 | AA49: 25수능
G51: *'도수분포 파일'로부터 응시인원 붙여넣기(과목순서 유의) | L51: *원점배치표 표점배치표 모두 필수입력
...

Sheet        가 군       
B1: 가 | C1: 나 | D1: 다 | E1: 가나다 | I1: 환산점수 배치표 (가 군) 2025학년도 수능 실채점기준
B2: 1 | C2: 2 | D2: 3 | E2: 4 | R2: 제작 및 검토 <베텔기우스> Betelgeuse058.tistory.com
B3: 군 입력
B4: 1 | C4: =IF($B$4=1,CONCATENATE($B$1,AE4),IF($B$4=2,CONCATENATE($C$1,AE4),IF($B$4=3,CONCATENATE($D$1,AE4),IF($B$4=4,CONCATENATE($E$1,AE4))))) -> 가
C5: =IFERROR(INDEX('배치점수 계산기'!A9:C9,MATCH(C4,'배치점수 계산기'!A7:C7,0)),) -> 0 | R5: 판정 기준점수
M6: 감점 상세 | P6: 나의 점수 | R6: 안정 | S6: 적정 | T6: 예상컷 | U6: 도전 | W6: 반영 방법 | Y6: 실질 반영비
E7: 공식 연번 | H7: 모집군 | I7: 대학 | J7: 학과 | K7: 계열 | L7: 지원가능 | M7: 영어감점 | N7: 영어감점 비율 | O7: 한국사/외국어 | P7: 합격확률 추정 | Q7: 환산점수 | R7: 0.9 | S7: 0.7 | T7: 0.4 | U7: 0.1 | V7: 0.03 | W7: 국 수 | X7: 탐구 | Y7: 국 | Z7: 수 | AA7: 탐 | AD7: 서식기준
C8: =_xlfn.CONCAT($C$4,G8) -> 가1 | D8: =MATCH($C8,'배치점수 계산기'!$O$11:$O$3001,0) -> 1 | E8: =OFFSET('배치점수 계산기'!A$10,D8,0) -> 5 | F8: =MATCH(E8,환산공식!$A$16:$A$301,0) -> 5 | G8: 1 | H8: =IFERROR(INDEX('배치점수 계산기'!C$11:C$3001,MATCH($C8,'배치점수 계산기'!$O$11:$O$3001,0)),"") -> 가 | I8: =IFERROR(INDEX('배치점수 계산기'!D$11:D$3001,MATCH($C8,'배치점수 계산기'!$O$11:$O$3001,0)),"") -> 연세대 | J8: =IFERROR(INDEX('배치점수 계산기'!E$11:E$3001,MATCH($C8,'배치점수 계산기'!$O$11:$O$3001,0)),"") -> 반도체 | K8: =IFERROR(INDEX('배치점수 계산기'!F$11:F$3001,MATCH($C8,'배치점수 계산기'!$O$11:$O$3001,0)),"") -> 자연 | L8: =IF(OFFSET(환산공식!$DU$15,$F8,0)=1,"O","X") -> X | M8: =IFERROR(OFFSET(환산공식!DA$15,$F8,0),"") -> 111.1 | N8: =IFERROR(CONCATENATE(ROUND(OFFSET(환산공식!DB$15,$F8,0),1),"%"),"") -> 100% | O8: =IFERROR(OFFSET(환산공식!DC$15,$F8,0),"") -> 10 | P8: =IF(E8="","",IF(Q8>R8,"90% 이상",IF(Q8>S8,CONCATENATE(ROUND(((Q8-S8)/(R8-S8))*20+70,0),"%"),IF(Q8>T8,CONCATENATE(ROUND(((Q8-T8)/(S8-T8))*30+40,0),"%"),IF(Q8>U8,CONCATENATE(ROUND(((Q8-U8)/(T8-U8))*30+10,0),"%"),IF(Q8>V8,CONCATENATE(ROUND(((Q8-V8)/(U8-V8))*7+3,0),"%"),"3% 이하")))))) -> 3% 이하 | Q8: =IFERROR(ROUND(OFFSET(환산공식!$EX$15,$F8,0),3),"") -> 0 | R8: =OFFSET('배치점수 계산기'!H$10,$D8,0) -> 711.155 | S8: =OFFSET('배치점수 계산기'!I$10,$D8,0) -> 710.747 | T8: =OFFSET('배치점수 계산기'!J$10,$D8,0) -> 709.964 | U8: =OFFSET('배치점수 계산기'!K$10,$D8,0) -> 705.794 | V8: =OFFSET('배치점수 계산기'!L$10,$D8,0) -> 701.412 | W8: =OFFSET('배치점수 계산기'!M$10,$D8,0) -> 표점 | X8: =OFFSET('배치점수 계산기'!N$10,$D8,0) -> 변표 | Y8: =OFFSET(환산공식!FG$15,$F8,0) -> 0.25 | Z8: =OFFSET(환산공식!FH$15,$F8,0) -> 0.38 | AA8: =OFFSET(환산공식!FI$15,$F8,0) -> 0.38 | AD8: =IF(L8="X",6,IF(Q8>R8,1,IF(Q8>S8,2,IF(Q8>T8,3,IF(Q8>U8,4,IF(Q8>=V8,5,IF(Q8<V8,6,""))))))) -> 6
C9: 가2 | D9: 2 | E9: 5 | F9: 5 | G9: 2 | H9: 가 | I9: 연세대 | J9: 전기전자 | K9: 자연 | L9: =IF(OFFSET(환산공식!$DU$15,$F9,0)=1,"O","X") -> X | M9: =IFERROR(OFFSET(환산공식!DA$15,$F9,0),"") -> 111.1 | N9: =IFERROR(CONCATENATE(ROUND(OFFSET(환산공식!DB$15,$F9,0),1),"%"),"") -> 100% | O9: =IFERROR(OFFSET(환산공식!DC$15,$F9,0),"") -> 10 | P9: =IF(E9="","",IF(Q9>R9,"90% 이상",IF(Q9>S9,CONCATENATE(ROUND(((Q9-S9)/(R9-S9))*20+70,0),"%"),IF(Q9>T9,CONCATENATE(ROUND(((Q9-T9)/(S9-T9))*30+40,0),"%"),IF(Q9>U9,CONCATENATE(ROUND(((Q9-U9)/(T9-U9))*30+10,0),"%"),IF(Q9>V9,CONCATENATE(ROUND(((Q9-V9)/(U9-V9))*7+3,0),"%"),"3% 이하")))))) -> 3% 이하 | Q9: =IFERROR(ROUND(OFFSET(환산공식!$EX$15,$F9,0),3),"") -> 0 | R9: =OFFSET('배치점수 계산기'!H$10,$D9,0) -> 710.339 | S9: =OFFSET('배치점수 계산기'!I$10,$D9,0) -> 709.964 | T9: =OFFSET('배치점수 계산기'!J$10,$D9,0) -> 707.723 | U9: =OFFSET('배치점수 계산기'!K$10,$D9,0) -> 706.369 | V9: =OFFSET('배치점수 계산기'!L$10,$D9,0) -> 702.252 | W9: =OFFSET('배치점수 계산기'!M$10,$D9,0) -> 표점 | X9: =OFFSET('배치점수 계산기'!N$10,$D9,0) -> 변표 | Y9: =OFFSET(환산공식!FG$15,$F9,0) -> 0.25 | Z9: =OFFSET(환산공식!FH$15,$F9,0) -> 0.38 | AA9: =OFFSET(환산공식!FI$15,$F9,0) -> 0.38 | AD9: =IF(L9="X",6,IF(Q9>R9,1,IF(Q9>S9,2,IF(Q9>T9,3,IF(Q9>U9,4,IF(Q9>=V9,5,IF(Q9<V9,6,""))))))) -> 6
C10: 가3 | D10: 3 | E10: 5 | F10: 5 | G10: 3 | H10: 가 | I10: 연세대 | J10: 신소재 | K10: 자연 | L10: =IF(OFFSET(환산공식!$DU$15,$F10,0)=1,"O","X") -> X | M10: =IFERROR(OFFSET(환산공식!DA$15,$F10,0),"") -> 111.1 | N10: =IFERROR(CONCATENATE(ROUND(OFFSET(환산공식!DB$15,$F10,0),1),"%"),"") -> 100% | O10: =IFERROR(OFFSET(환산공식!DC$15,$F10,0),"") -> 10 | P10: =IF(E10="","",IF(Q10>R10,"90% 이상",IF(Q10>S10,CONCATENATE(ROUND(((Q10-S10)/(R10-S10))*20+70,0),"%"),IF(Q10>T10,CONCATENATE(ROUND(((Q10-T10)/(S10-T10))*30+40,0),"%"),IF(Q10>U10,CONCATENATE(ROUND(((Q10-U10)/(T10-U10))*30+10,0),"%"),IF(Q10>V10,CONCATENATE(ROUND(((Q10-V10)/(U10-V10))*7+3,0),"%"),"3% 이하")))))) -> 3% 이하 | Q10: =IFERROR(ROUND(OFFSET(환산공식!$EX$15,$F10,0),3),"") -> 0 | R10: =OFFSET('배치점수 계산기'!H$10,$D10,0) -> 709.853 | S10: =OFFSET('배치점수 계산기'!I$10,$D10,0) -> 709.029 | T10: =OFFSET('배치점수 계산기'!J$10,$D10,0) -> 707.723 | U10: =OFFSET('배치점수 계산기'!K$10,$D10,0) -> 706.147 | V10: =OFFSET('배치점수 계산기'!L$10,$D10,0) -> 703.714 | W10: =OFFSET('배치점수 계산기'!M$10,$D10,0) -> 표점 | X10: =OFFSET('배치점수 계산기'!N$10,$D10,0) -> 변표 | Y10: =OFFSET(환산공식!FG$15,$F10,0) -> 0.25 | Z10: =OFFSET(환산공식!FH$15,$F10,0) -> 0.38 | AA10: =OFFSET(환산공식!FI$15,$F10,0) -> 0.38 | AD10: =IF(L10="X",6,IF(Q10>R10,1,IF(Q10>S10,2,IF(Q10>T10,3,IF(Q10>U10,4,IF(Q10>=V10,5,IF(Q10<V10,6,""))))))) -> 6
C11: 가4 | D11: 4 | E11: 5 | F11: 5 | G11: 4 | H11: 가 | I11: 연세대 | J11: 화생공 | K11: 자연 | L11: =IF(OFFSET(환산공식!$DU$15,$F11,0)=1,"O","X") -> X | M11: =IFERROR(OFFSET(환산공식!DA$15,$F11,0),"") -> 111.1 | N11: =IFERROR(CONCATENATE(ROUND(OFFSET(환산공식!DB$15,$F11,0),1),"%"),"") -> 100% | O11: =IFERROR(OFFSET(환산공식!DC$15,$F11,0),"") -> 10 | P11: =IF(E11="","",IF(Q11>R11,"90% 이상",IF(Q11>S11,CONCATENATE(ROUND(((Q11-S11)/(R11-S11))*20+70,0),"%"),IF(Q11>T11,CONCATENATE(ROUND(((Q11-T11)/(S11-T11))*30+40,0),"%"),IF(Q11>U11,CONCATENATE(ROUND(((Q11-U11)/(T11-U11))*30+10,0),"%"),IF(Q11>V11,CONCATENATE(ROUND(((Q11-V11)/(U11-V11))*7+3,0),"%"),"3% 이하")))))) -> 3% 이하 | Q11: =IFERROR(ROUND(OFFSET(환산공식!$EX$15,$F11,0),3),"") -> 0 | R11: =OFFSET('배치점수 계산기'!H$10,$D11,0) -> 709.853 | S11: =OFFSET('배치점수 계산기'!I$10,$D11,0) -> 709.029 | T11: =OFFSET('배치점수 계산기'!J$10,$D11,0) -> 707.723 | U11: =OFFSET('배치점수 계산기'!K$10,$D11,0) -> 704.564 | V11: =OFFSET('배치점수 계산기'!L$10,$D11,0) -> 698.604 | W11: =OFFSET('배치점수 계산기'!M$10,$D11,0) -> 표점 | X11: =OFFSET('배치점수 계산기'!N$10,$D11,0) -> 변표 | Y11: =OFFSET(환산공식!FG$15,$F11,0) -> 0.25 | Z11: =OFFSET(환산공식!FH$15,$F11,0) -> 0.38 | AA11: =OFFSET(환산공식!FI$15,$F11,0) -> 0.38 | AD11: =IF(L11="X",6,IF(Q11>R11,1,IF(Q11>S11,2,IF(Q11>T11,3,IF(Q11>U11,4,IF(Q11>=V11,5,IF(Q11<V11,6,""))))))) -> 6
C12: 가5 | D12: 5 | E12: 5 | F12: 5 | G12: 5 | H12: 가 | I12: 연세대 | J12: 인공지능 | K12: 자연 | L12: =IF(OFFSET(환산공식!$DU$15,$F12,0)=1,"O","X") -> X | M12: =IFERROR(OFFSET(환산공식!DA$15,$F12,0),"") -> 111.1 | N12: =IFERROR(CONCATENATE(ROUND(OFFSET(환산공식!DB$15,$F12,0),1),"%"),"") -> 100% | O12: =IFERROR(OFFSET(환산공식!DC$15,$F12,0),"") -> 10 | P12: =IF(E12="","",IF(Q12>R12,"90% 이상",IF(Q12>S12,CONCATENATE(ROUND(((Q12-S12)/(R12-S12))*20+70,0),"%"),IF(Q12>T12,CONCATENATE(ROUND(((Q12-T12)/(S12-T12))*30+40,0),"%"),IF(Q12>U12,CONCATENATE(ROUND(((Q12-U12)/(T12-U12))*30+10,0),"%"),IF(Q12>V12,CONCATENATE(ROUND(((Q12-V12)/(U12-V12))*7+3,0),"%"),"3% 이하")))))) -> 3% 이하 | Q12: =IFERROR(ROUND(OFFSET(환산공식!$EX$15,$F12,0),3),"") -> 0 | R12: =OFFSET('배치점수 계산기'!H$10,$D12,0) -> 709.853 | S12: =OFFSET('배치점수 계산기'!I$10,$D12,0) -> 708.436 | T12: =OFFSET('배치점수 계산기'!J$10,$D12,0) -> 706.962 | U12: =OFFSET('배치점수 계산기'!K$10,$D12,0) -> 704.026 | V12: =OFFSET('배치점수 계산기'!L$10,$D12,0) -> 698.493 | W12: =OFFSET('배치점수 계산기'!M$10,$D12,0) -> 표점 | X12: =OFFSET('배치점수 계산기'!N$10,$D12,0) -> 변표 | Y12: =OFFSET(환산공식!FG$15,$F12,0) -> 0.25 | Z12: =OFFSET(환산공식!FH$15,$F12,0) -> 0.38 | AA12: =OFFSET(환산공식!FI$15,$F12,0) -> 0.38 | AD12: =IF(L12="X",6,IF(Q12>R12,1,IF(Q12>S12,2,IF(Q12>T12,3,IF(Q12>U12,4,IF(Q12>=V12,5,IF(Q12<V12,6,""))))))) -> 6
C13: 가6 | D13: 6 | E13: 5 | F13: 5 | G13: 6 | H13: 가 | I13: 연세대 | J13: 기계 | K13: 자연 | L13: =IF(OFFSET(환산공식!$DU$15,$F13,0)=1,"O","X") -> X | M13: =IFERROR(OFFSET(환산공식!DA$15,$F13,0),"") -> 111.1 | N13: =IFERROR(CONCATENATE(ROUND(OFFSET(환산공식!DB$15,$F13,0),1),"%"),"") -> 100% | O13: =IFERROR(OFFSET(환산공식!DC$15,$F13,0),"") -> 10 | P13: =IF(E13="","",IF(Q13>R13,"90% 이상",IF(Q13>S13,CONCATENATE(ROUND(((Q13-S13)/(R13-S13))*20+70,0),"%"),IF(Q13>T13,CONCATENATE(ROUND(((Q13-T13)/(S13-T13))*30+40,0),"%"),IF(Q13>U13,CONCATENATE(ROUND(((Q13-U13)/(T13-U13))*30+10,0),"%"),IF(Q13>V13,CONCATENATE(ROUND(((Q13-V13)/(U13-V13))*7+3,0),"%"),"3% 이하")))))) -> 3% 이하 | Q13: =IFERROR(ROUND(OFFSET(환산공식!$EX$15,$F13,0),3),"") -> 0 | R13: =OFFSET('배치점수 계산기'!H$10,$D13,0) -> 709.37 | S13: =OFFSET('배치점수 계산기'!I$10,$D13,0) -> 708.436 | T13: =OFFSET('배치점수 계산기'!J$10,$D13,0) -> 706.962 | U13: =OFFSET('배치점수 계산기'!K$10,$D13,0) -> 705.572 | V13: =OFFSET('배치점수 계산기'!L$10,$D13,0) -> 703.714 | W13: =OFFSET('배치점수 계산기'!M$10,$D13,0) -> 표점 | X13: =OFFSET('배치점수 계산기'!N$10,$D13,0) -> 변표 | Y13: =OFFSET(환산공식!FG$15,$F13,0) -> 0.25 | Z13: =OFFSET(환산공식!FH$15,$F13,0) -> 0.38 | AA13: =OFFSET(환산공식!FI$15,$F13,0) -> 0.38 | AD13: =IF(L13="X",6,IF(Q13>R13,1,IF(Q13>S13,2,IF(Q13>T13,3,IF(Q13>U13,4,IF(Q13>=V13,5,IF(Q13<V13,6,""))))))) -> 6
C14: 가7 | D14: 7 | E14: 5 | F14: 5 | G14: 7 | H14: 가 | I14: 연세대 | J14: 화학 | K14: 자연 | L14: =IF(OFFSET(환산공식!$DU$15,$F14,0)=1,"O","X") -> X | M14: =IFERROR(OFFSET(환산공식!DA$15,$F14,0),"") -> 111.1 | N14: =IFERROR(CONCATENATE(ROUND(OFFSET(환산공식!DB$15,$F14,0),1),"%"),"") -> 100% | O14: =IFERROR(OFFSET(환산공식!DC$15,$F14,0),"") -> 10 | P14: =IF(E14="","",IF(Q14>R14,"90% 이상",IF(Q14>S14,CONCATENATE(ROUND(((Q14-S14)/(R14-S14))*20+70,0),"%"),IF(Q14>T14,CONCATENATE(ROUND(((Q14-T14)/(S14-T14))*30+40,0),"%"),IF(Q14>U14,CONCATENATE(ROUND(((Q14-U14)/(T14-U14))*30+10,0),"%"),IF(Q14>V14,CONCATENATE(ROUND(((Q14-V14)/(U14-V14))*7+3,0),"%"),"3% 이하")))))) -> 3% 이하 | Q14: =IFERROR(ROUND(OFFSET(환산공식!$EX$15,$F14,0),3),"") -> 0 | R14: =OFFSET('배치점수 계산기'!H$10,$D14,0) -> 708.918 | S14: =OFFSET('배치점수 계산기'!I$10,$D14,0) -> 707.723 | T14: =OFFSET('배치점수 계산기'!J$10,$D14,0) -> 706.147 | U14: =OFFSET('배치점수 계산기'!K$10,$D14,0) -> 704.564 | V14: =OFFSET('배치점수 계산기'!L$10,$D14,0) -> 703.231 | W14: =OFFSET('배치점수 계산기'!M$10,$D14,0) -> 표점 | X14: =OFFSET('배치점수 계산기'!N$10,$D14,0) -> 변표 | Y14: =OFFSET(환산공식!FG$15,$F14,0) -> 0.25 | Z14: =OFFSET(환산공식!FH$15,$F14,0) -> 0.38 | AA14: =OFFSET(환산공식!FI$15,$F14,0) -> 0.38 | AD14: =IF(L14="X",6,IF(Q14>R14,1,IF(Q14>S14,2,IF(Q14>T14,3,IF(Q14>U14,4,IF(Q14>=V14,5,IF(Q14<V14,6,""))))))) -> 6
C15: 가8 | D15: 8 | E15: 5 | F15: 5 | G15: 8 | H15: 가 | I15: 연세대 | J15: 컴퓨터 | K15: 자연 | L15: =IF(OFFSET(환산공식!$DU$15,$F15,0)=1,"O","X") -> X | M15: =IFERROR(OFFSET(환산공식!DA$15,$F15,0),"") -> 111.1 | N15: =IFERROR(CONCATENATE(ROUND(OFFSET(환산공식!DB$15,$F15,0),1),"%"),"") -> 100% | O15: =IFERROR(OFFSET(환산공식!DC$15,$F15,0),"") -> 10 | P15: =IF(E15="","",IF(Q15>R15,"90% 이상",IF(Q15>S15,CONCATENATE(ROUND(((Q15-S15)/(R15-S15))*20+70,0),"%"),IF(Q15>T15,CONCATENATE(ROUND(((Q15-T15)/(S15-T15))*30+40,0),"%"),IF(Q15>U15,CONCATENATE(ROUND(((Q15-U15)/(T15-U15))*30+10,0),"%"),IF(Q15>V15,CONCATENATE(ROUND(((Q15-V15)/(U15-V15))*7+3,0),"%"),"3% 이하")))))) -> 3% 이하 | Q15: =IFERROR(ROUND(OFFSET(환산공식!$EX$15,$F15,0),3),"") -> 0 | R15: =OFFSET('배치점수 계산기'!H$10,$D15,0) -> 710.339 | S15: =OFFSET('배치점수 계산기'!I$10,$D15,0) -> 709.37 | T15: =OFFSET('배치점수 계산기'!J$10,$D15,0) -> 705.794 | U15: =OFFSET('배치점수 계산기'!K$10,$D15,0) -> 703.231 | V15: =OFFSET('배치점수 계산기'!L$10,$D15,0) -> 702.252 | W15: =OFFSET('배치점수 계산기'!M$10,$D15,0) -> 표점 | X15: =OFFSET('배치점수 계산기'!N$10,$D15,0) -> 변표 | Y15: =OFFSET(환산공식!FG$15,$F15,0) -> 0.25 | Z15: =OFFSET(환산공식!FH$15,$F15,0) -> 0.38 | AA15: =OFFSET(환산공식!FI$15,$F15,0) -> 0.38 | AD15: =IF(L15="X",6,IF(Q15>R15,1,IF(Q15>S15,2,IF(Q15>T15,3,IF(Q15>U15,4,IF(Q15>=V15,5,IF(Q15<V15,6,""))))))) -> 6
C16: 가9 | D16: 9 | E16: 5 | F16: 5 | G16: 9 | H16: 가 | I16: 연세대 | J16: 수학 | K16: 자연 | L16: =IF(OFFSET(환산공식!$DU$15,$F16,0)=1,"O","X") -> X | M16: =IFERROR(OFFSET(환산공식!DA$15,$F16,0),"") -> 111.1 | N16: =IFERROR(CONCATENATE(ROUND(OFFSET(환산공식!DB$15,$F16,0),1),"%"),"") -> 100% | O16: =IFERROR(OFFSET(환산공식!DC$15,$F16,0),"") -> 10 | P16: =IF(E16="","",IF(Q16>R16,"90% 이상",IF(Q16>S16,CONCATENATE(ROUND(((Q16-S16)/(R16-S16))*20+70,0),"%"),IF(Q16>T16,CONCATENATE(ROUND(((Q16-T16)/(S16-T16))*30+40,0),"%"),IF(Q16>U16,CONCATENATE(ROUND(((Q16-U16)/(T16-U16))*30+10,0),"%"),IF(Q16>V16,CONCATENATE(ROUND(((Q16-V16)/(U16-V16))*7+3,0),"%"),"3% 이하")))))) -> 3% 이하 | Q16: =IFERROR(ROUND(OFFSET(환산공식!$EX$15,$F16,0),3),"") -> 0 | R16: =OFFSET('배치점수 계산기'!H$10,$D16,0) -> 708.918 | S16: =OFFSET('배치점수 계산기'!I$10,$D16,0) -> 707.723 | T16: =OFFSET('배치점수 계산기'!J$10,$D16,0) -> 705.794 | U16: =OFFSET('배치점수 계산기'!K$10,$D16,0) -> 704.675 | V16: =OFFSET('배치점수 계산기'!L$10,$D16,0) -> 703.231 | W16: =OFFSET('배치점수 계산기'!M$10,$D16,0) -> 표점 | X16: =OFFSET('배치점수 계산기'!N$10,$D16,0) -> 변표 | Y16: =OFFSET(환산공식!FG$15,$F16,0) -> 0.25 | Z16: =OFFSET(환산공식!FH$15,$F16,0) -> 0.38 | AA16: =OFFSET(환산공식!FI$15,$F16,0) -> 0.38 | AD16: =IF(L16="X",6,IF(Q16>R16,1,IF(Q16>S16,2,IF(Q16>T16,3,IF(Q16>U16,4,IF(Q16>=V16,5,IF(Q16<V16,6,""))))))) -> 6
C17: 가10 | D17: 10 | E17: 5 | F17: 5 | G17: 10 | H17: 가 | I17: 연세대 | J17: 생명공학 | K17: 자연 | L17: =IF(OFFSET(환산공식!$DU$15,$F17,0)=1,"O","X") -> X | M17: =IFERROR(OFFSET(환산공식!DA$15,$F17,0),"") -> 111.1 | N17: =IFERROR(CONCATENATE(ROUND(OFFSET(환산공식!DB$15,$F17,0),1),"%"),"") -> 100% | O17: =IFERROR(OFFSET(환산공식!DC$15,$F17,0),"") -> 10 | P17: =IF(E17="","",IF(Q17>R17,"90% 이상",IF(Q17>S17,CONCATENATE(ROUND(((Q17-S17)/(R17-S17))*20+70,0),"%"),IF(Q17>T17,CONCATENATE(ROUND(((Q17-T17)/(S17-T17))*30+40,0),"%"),IF(Q17>U17,CONCATENATE(ROUND(((Q17-U17)/(T17-U17))*30+10,0),"%"),IF(Q17>V17,CONCATENATE(ROUND(((Q17-V17)/(U17-V17))*7+3,0),"%"),"3% 이하")))))) -> 3% 이하 | Q17: =IFERROR(ROUND(OFFSET(환산공식!$EX$15,$F17,0),3),"") -> 0 | R17: =OFFSET('배치점수 계산기'!H$10,$D17,0) -> 708.308 | S17: =OFFSET('배치점수 계산기'!I$10,$D17,0) -> 707.406 | T17: =OFFSET('배치점수 계산기'!J$10,$D17,0) -> 705.794 | U17: =OFFSET('배치점수 계산기'!K$10,$D17,0) -> 702.252 | V17: =OFFSET('배치점수 계산기'!L$10,$D17,0) -> 697.597 | W17: =OFFSET('배치점수 계산기'!M$10,$D17,0) -> 표점 | X17: =OFFSET('배치점수 계산기'!N$10,$D17,0) -> 변표 | Y17: =OFFSET(환산공식!FG$15,$F17,0) -> 0.25 | Z17: =OFFSET(환산공식!FH$15,$F17,0) -> 0.38 | AA17: =OFFSET(환산공식!FI$15,$F17,0) -> 0.38 | AD17: =IF(L17="X",6,IF(Q17>R17,1,IF(Q17>S17,2,IF(Q17>T17,3,IF(Q17>U17,4,IF(Q17>=V17,5,IF(Q17<V17,6,""))))))) -> 6
C18: 가11 | D18: 11 | E18: 5 | F18: 5 | G18: 11 | H18: 가 | I18: 연세대 | J18: 산업 | K18: 자연 | L18: =IF(OFFSET(환산공식!$DU$15,$F18,0)=1,"O","X") -> X | M18: =IFERROR(OFFSET(환산공식!DA$15,$F18,0),"") -> 111.1 | N18: =IFERROR(CONCATENATE(ROUND(OFFSET(환산공식!DB$15,$F18,0),1),"%"),"") -> 100% | O18: =IFERROR(OFFSET(환산공식!DC$15,$F18,0),"") -> 10 | P18: =IF(E18="","",IF(Q18>R18,"90% 이상",IF(Q18>S18,CONCATENATE(ROUND(((Q18-S18)/(R18-S18))*20+70,0),"%"),IF(Q18>T18,CONCATENATE(ROUND(((Q18-T18)/(S18-T18))*30+40,0),"%"),IF(Q18>U18,CONCATENATE(ROUND(((Q18-U18)/(T18-U18))*30+10,0),"%"),IF(Q18>V18,CONCATENATE(ROUND(((Q18-V18)/(U18-V18))*7+3,0),"%"),"3% 이하")))))) -> 3% 이하 | Q18: =IFERROR(ROUND(OFFSET(환산공식!$EX$15,$F18,0),3),"") -> 0 | R18: =OFFSET('배치점수 계산기'!H$10,$D18,0) -> 708.308 | S18: =OFFSET('배치점수 계산기'!I$10,$D18,0) -> 706.962 | T18: =OFFSET('배치점수 계산기'!J$10,$D18,0) -> 705.271 | U18: =OFFSET('배치점수 계산기'!K$10,$D18,0) -> 702.568 | V18: =OFFSET('배치점수 계산기'!L$10,$D18,0) -> 698.604 | W18: =OFFSET('배치점수 계산기'!M$10,$D18,0) -> 표점 | X18: =OFFSET('배치점수 계산기'!N$10,$D18,0) -> 변표 | Y18: =OFFSET(환산공식!FG$15,$F18,0) -> 0.25 | Z18: =OFFSET(환산공식!FH$15,$F18,0) -> 0.38 | AA18: =OFFSET(환산공식!FI$15,$F18,0) -> 0.38 | AD18: =IF(L18="X",6,IF(Q18>R18,1,IF(Q18>S18,2,IF(Q18>T18,3,IF(Q18>U18,4,IF(Q18>=V18,5,IF(Q18<V18,6,""))))))) -> 6
C19: 가12 | D19: 12 | E19: 5 | F19: 5 | G19: 12 | H19: 가 | I19: 연세대 | J19: 생화학 | K19: 자연 | L19: =IF(OFFSET(환산공식!$DU$15,$F19,0)=1,"O","X") -> X | M19: =IFERROR(OFFSET(환산공식!DA$15,$F19,0),"") -> 111.1 | N19: =IFERROR(CONCATENATE(ROUND(OFFSET(환산공식!DB$15,$F19,0),1),"%"),"") -> 100% | O19: =IFERROR(OFFSET(환산공식!DC$15,$F19,0),"") -> 10 | P19: =IF(E19="","",IF(Q19>R19,"90% 이상",IF(Q19>S19,CONCATENATE(ROUND(((Q19-S19)/(R19-S19))*20+70,0),"%"),IF(Q19>T19,CONCATENATE(ROUND(((Q19-T19)/(S19-T19))*30+40,0),"%"),IF(Q19>U19,CONCATENATE(ROUND(((Q19-U19)/(T19-U19))*30+10,0),"%"),IF(Q19>V19,CONCATENATE(ROUND(((Q19-V19)/(U19-V19))*7+3,0),"%"),"3% 이하")))))) -> 3% 이하 | Q19: =IFERROR(ROUND(OFFSET(환산공식!$EX$15,$F19,0),3),"") -> 0 | R19: =OFFSET('배치점수 계산기'!H$10,$D19,0) -> 708.918 | S19: =OFFSET('배치점수 계산기'!I$10,$D19,0) -> 706.962 | T19: =OFFSET('배치점수 계산기'!J$10,$D19,0) -> 705.271 | U19: =OFFSET('배치점수 계산기'!K$10,$D19,0) -> 704.026 | V19: =OFFSET('배치점수 계산기'!L$10,$D19,0) -> 701.523 | W19: =OFFSET('배치점수 계산기'!M$10,$D19,0) -> 표점 | X19: =OFFSET('배치점수 계산기'!N$10,$D19,0) -> 변표 | Y19: =OFFSET(환산공식!FG$15,$F19,0) -> 0.25 | Z19: =OFFSET(환산공식!FH$15,$F19,0) -> 0.38 | AA19: =OFFSET(환산공식!FI$15,$F19,0) -> 0.38 | AD19: =IF(L19="X",6,IF(Q19>R19,1,IF(Q19>S19,2,IF(Q19>T19,3,IF(Q19>U19,4,IF(Q19>=V19,5,IF(Q19<V19,6,""))))))) -> 6
C20: 가13 | D20: 13 | E20: 5 | F20: 5 | G20: 13 | H20: 가 | I20: 연세대 | J20: 디스플레이 | K20: 자연 | L20: =IF(OFFSET(환산공식!$DU$15,$F20,0)=1,"O","X") -> X | M20: =IFERROR(OFFSET(환산공식!DA$15,$F20,0),"") -> 111.1 | N20: =IFERROR(CONCATENATE(ROUND(OFFSET(환산공식!DB$15,$F20,0),1),"%"),"") -> 100% | O20: =IFERROR(OFFSET(환산공식!DC$15,$F20,0),"") -> 10 | P20: =IF(E20="","",IF(Q20>R20,"90% 이상",IF(Q20>S20,CONCATENATE(ROUND(((Q20-S20)/(R20-S20))*20+70,0),"%"),IF(Q20>T20,CONCATENATE(ROUND(((Q20-T20)/(S20-T20))*30+40,0),"%"),IF(Q20>U20,CONCATENATE(ROUND(((Q20-U20)/(T20-U20))*30+10,0),"%"),IF(Q20>V20,CONCATENATE(ROUND(((Q20-V20)/(U20-V20))*7+3,0),"%"),"3% 이하")))))) -> 3% 이하 | Q20: =IFERROR(ROUND(OFFSET(환산공식!$EX$15,$F20,0),3),"") -> 0 | R20: =OFFSET('배치점수 계산기'!H$10,$D20,0) -> 707.723 | S20: =OFFSET('배치점수 계산기'!I$10,$D20,0) -> 706.369 | T20: =OFFSET('배치점수 계산기'!J$10,$D20,0) -> 704.937 | U20: =OFFSET('배치점수 계산기'!K$10,$D20,0) -> 704.026 | V20: =OFFSET('배치점수 계산기'!L$10,$D20,0) -> 698.493 | W20: =OFFSET('배치점수 계산기'!M$10,$D20,0) -> 표점 | X20: =OFFSET('배치점수 계산기'!N$10,$D20,0) -> 변표 | Y20: =OFFSET(환산공식!FG$15,$F20,0) -> 0.25 | Z20: =OFFSET(환산공식!FH$15,$F20,0) -> 0.38 | AA20: =OFFSET(환산공식!FI$15,$F20,0) -> 0.38 | AD20: =IF(L20="X",6,IF(Q20>R20,1,IF(Q20>S20,2,IF(Q20>T20,3,IF(Q20>U20,4,IF(Q20>=V20,5,IF(Q20<V20,6,""))))))) -> 6
... C898: 가891 | D898: 902 | E898: 87 | F898: 87 | G898: 891 | H898: 가 | I898: 이화여대 | J898: 초등교 | K898: 통합 | L898: =IF(OFFSET(환산공식!$DU$15,$F898,0)=1,"O","X") -> X | M898: =IFERROR(OFFSET(환산공식!DA$15,$F898,0),"") -> 200 | N898: =IFERROR(CONCATENATE(ROUND(OFFSET(환산공식!DB$15,$F898,0),1),"%"),"") -> 100% | O898: =IFERROR(OFFSET(환산공식!DC$15,$F898,0),"") -> 10 | P898: =IF(E898="","",IF(Q898>R898,"90% 이상",IF(Q898>S898,CONCATENATE(ROUND(((Q898-S898)/(R898-S898))*20+70,0),"%"),IF(Q898>T898,CONCATENATE(ROUND(((Q898-T898)/(S898-T898))*30+40,0),"%"),IF(Q898>U898,CONCATENATE(ROUND(((Q898-U898)/(T898-U898))*30+10,0),"%"),IF(Q898>V898,CONCATENATE(ROUND(((Q898-V898)/(U898-V898))*7+3,0),"%"),"3% 이하")))))) -> 3% 이하 | Q898: =IFERROR(ROUND(OFFSET(환산공식!$EX$15,$F898,0),3),"") -> 0 | R898: =OFFSET('배치점수 계산기'!H$10,$D898,0) -> 937.351 | S898: =OFFSET('배치점수 계산기'!I$10,$D898,0) -> 935.859 | T898: =OFFSET('배치점수 계산기'!J$10,$D898,0) -> 932.346 | U898: =OFFSET('배치점수 계산기'!K$10,$D898,0) -> 928.401 | V898: =OFFSET('배치점수 계산기'!L$10,$D898,0) -> 924.162 | W898: =OFFSET('배치점수 계산기'!M$10,$D898,0) -> 표점/만점 | X898: =OFFSET('배치점수 계산기'!N$10,$D898,0) -> 변표/만점 | Y898: =OFFSET(환산공식!FG$15,$F898,0) -> 0.37 | Z898: =OFFSET(환산공식!FH$15,$F898,0) -> 0.37 | AA898: =OFFSET(환산공식!FI$15,$F898,0) -> 0.26 | AD898: =IF(L898="X",6,IF(Q898>R898,1,IF(Q898>S898,2,IF(Q898>T898,3,IF(Q898>U898,4,IF(Q898>=V898,5,IF(Q898<V898,6,""))))))) -> 6
C899: =_xlfn.CONCAT($C$4,G899) -> 가892 | D899: =MATCH($C899,'배치점수 계산기'!$O$11:$O$3001,0) -> #N/A | E899: =OFFSET('배치점수 계산기'!A$10,D899,0) -> #N/A | F899: =MATCH(E899,환산공식!$A$16:$A$301,0) -> #N/A | G899: 892 | AD899: =IF(L899="X",6,IF(Q899>R899,1,IF(Q899>S899,2,IF(Q899>T899,3,IF(Q899>U899,4,IF(Q899>=V899,5,IF(Q899<V899,6,""))))))) -> 5
C900: =_xlfn.CONCAT($C$4,G900) -> 가893 | D900: =MATCH($C900,'배치점수 계산기'!$O$11:$O$3001,0) -> #N/A | E900: =OFFSET('배치점수 계산기'!A$10,D900,0) -> #N/A | F900: =MATCH(E900,환산공식!$A$16:$A$301,0) -> #N/A | G900: 893 | AD900: =IF(L900="X",6,IF(Q900>R900,1,IF(Q900>S900,2,IF(Q900>T900,3,IF(Q900>U900,4,IF(Q900>=V900,5,IF(Q900<V900,6,""))))))) -> 5

Sheet        나 군       
B1: 가 | C1: 나 | D1: 다 | E1: 가나다 | I1: 환산점수 배치표 (나 군) 2025학년도 수능 실채점기준
B2: 1 | C2: 2 | D2: 3 | E2: 4 | R2: 제작 및 검토 <베텔기우스> Betelgeuse058.tistory.com
B3: 군 입력
B4: 2 | C4: =IF($B$4=1,CONCATENATE($B$1,AE4),IF($B$4=2,CONCATENATE($C$1,AE4),IF($B$4=3,CONCATENATE($D$1,AE4),IF($B$4=4,CONCATENATE($E$1,AE4))))) -> 나
C5: =IFERROR(INDEX('배치점수 계산기'!A9:C9,MATCH(C4,'배치점수 계산기'!A7:C7,0)),) -> 901 | R5: 판정 기준점수
M6: 감점 상세 | P6: 나의 점수 | R6: 안정 | S6: 적정 | T6: 예상컷 | U6: 도전 | W6: 반영 방법 | Y6: 실질 반영비
E7: 공식 연번 | H7: 모집군 | I7: 대학 | J7: 학과 | K7: 계열 | L7: 지원가능 | M7: 영어감점 | N7: 영어감점 비율 | O7: 한국사/외국어 | P7: 합격확률 추정 | Q7: 환산점수 | R7: 0.9 | S7: 0.7 | T7: 0.4 | U7: 0.1 | V7: 0.03 | W7: 국 수 | X7: 탐구 | Y7: 국 | Z7: 수 | AA7: 탐 | AD7: 서식기준
C8: =_xlfn.CONCAT($C$4,G8) -> 나1 | D8: =MATCH($C8,'배치점수 계산기'!$O$11:$O$3001,0) -> 903 | E8: =OFFSET('배치점수 계산기'!A$10,D8,0) -> 2 | F8: =MATCH(E8,환산공식!$A$16:$A$301,0) -> 2 | G8: 1 | H8: =IFERROR(INDEX('배치점수 계산기'!C$11:C$3001,MATCH($C8,'배치점수 계산기'!$O$11:$O$3001,0)),"") -> 나 | I8: =IFERROR(INDEX('배치점수 계산기'!D$11:D$3001,MATCH($C8,'배치점수 계산기'!$O$11:$O$3001,0)),"") -> 서울대 | J8: =IFERROR(INDEX('배치점수 계산기'!E$11:E$3001,MATCH($C8,'배치점수 계산기'!$O$11:$O$3001,0)),"") -> 수리과학 | K8: =IFERROR(INDEX('배치점수 계산기'!F$11:F$3001,MATCH($C8,'배치점수 계산기'!$O$11:$O$3001,0)),"") -> 자연 | L8: =IF(OFFSET(환산공식!$DU$15,$F8,0)=1,"O","X") -> X | M8: =IFERROR(OFFSET(환산공식!DA$15,$F8,0),"") -> 0 | N8: =IFERROR(CONCATENATE(ROUND(OFFSET(환산공식!DB$15,$F8,0),1),"%"),"") | O8: =IFERROR(OFFSET(환산공식!DC$15,$F8,0),"") -> 0 | P8: =IF(E8="","",IF(Q8>R8,"90% 이상",IF(Q8>S8,CONCATENATE(ROUND(((Q8-S8)/(R8-S8))*20+70,0),"%"),IF(Q8>T8,CONCATENATE(ROUND(((Q8-T8)/(S8-T8))*30+40,0),"%"),IF(Q8>U8,CONCATENATE(ROUND(((Q8-U8)/(T8-U8))*30+10,0),"%"),IF(Q8>V8,CONCATENATE(ROUND(((Q8-V8)/(U8-V8))*7+3,0),"%"),"3% 이하")))))) -> 3% 이하 | Q8: =IFERROR(ROUND(OFFSET(환산공식!$EX$15,$F8,0),3),"") -> 0 | R8: =OFFSET('배치점수 계산기'!H$10,$D8,0) -> 407.92 | S8: =OFFSET('배치점수 계산기'!I$10,$D8,0) -> 407.4 | T8: =OFFSET('배치점수 계산기'!J$10,$D8,0) -> 406.08 | U8: =OFFSET('배치점수 계산기'!K$10,$D8,0) -> 401.64 | V8: =OFFSET('배치점수 계산기'!L$10,$D8,0) -> 398.65 | W8: =OFFSET('배치점수 계산기'!M$10,$D8,0) -> 표점 | X8: =OFFSET('배치점수 계산기'!N$10,$D8,0) -> 표점 | Y8: =OFFSET(환산공식!FG$15,$F8,0) -> 0.33 | Z8: =OFFSET(환산공식!FH$15,$F8,0) -> 0.4 | AA8: =OFFSET(환산공식!FI$15,$F8,0) -> 0.27 | AD8: =IF(L8="X",6,IF(Q8>R8,1,IF(Q8>S8,2,IF(Q8>T8,3,IF(Q8>U8,4,IF(Q8>=V8,5,IF(Q8<V8,6,""))))))) -> 6
C9: 나2 | D9: 904 | E9: 1 | F9: 1 | G9: 2 | H9: 나 | I9: 서울대 | J9: 전기정보공 | K9: 자연 | L9: =IF(OFFSET(환산공식!$DU$15,$F9,0)=1,"O","X") -> X | M9: =IFERROR(OFFSET(환산공식!DA$15,$F9,0),"") -> 0 | N9: =IFERROR(CONCATENATE(ROUND(OFFSET(환산공식!DB$15,$F9,0),1),"%"),"") | O9: =IFERROR(OFFSET(환산공식!DC$15,$F9,0),"") -> 0 | P9: =IF(E9="","",IF(Q9>R9,"90% 이상",IF(Q9>S9,CONCATENATE(ROUND(((Q9-S9)/(R9-S9))*20+70,0),"%"),IF(Q9>T9,CONCATENATE(ROUND(((Q9-T9)/(S9-T9))*30+40,0),"%"),IF(Q9>U9,CONCATENATE(ROUND(((Q9-U9)/(T9-U9))*30+10,0),"%"),IF(Q9>V9,CONCATENATE(ROUND(((Q9-V9)/(U9-V9))*7+3,0),"%"),"3% 이하")))))) -> 3% 이하 | Q9: =IFERROR(ROUND(OFFSET(환산공식!$EX$15,$F9,0),3),"") -> 0 | R9: =OFFSET('배치점수 계산기'!H$10,$D9,0) -> 406.48 | S9: =OFFSET('배치점수 계산기'!I$10,$D9,0) -> 405.46 | T9: =OFFSET('배치점수 계산기'!J$10,$D9,0) -> 404.27 | U9: =OFFSET('배치점수 계산기'!K$10,$D9,0) -> 403.25 | V9: =OFFSET('배치점수 계산기'!L$10,$D9,0) -> 398.28 | W9: =OFFSET('배치점수 계산기'!M$10,$D9,0) -> 표점 | X9: =OFFSET('배치점수 계산기'!N$10,$D9,0) -> 표점 | Y9: =OFFSET(환산공식!FG$15,$F9,0) -> 0.33 | Z9: =OFFSET(환산공식!FH$15,$F9,0) -> 0.4 | AA9: =OFFSET(환산공식!FI$15,$F9,0) -> 0.27 | AD9: =IF(L9="X",6,IF(Q9>R9,1,IF(Q9>S9,2,IF(Q9>T9,3,IF(Q9>U9,4,IF(Q9>=V9,5,IF(Q9<V9,6,""))))))) -> 6
C10: 나3 | D10: 905 | E10: 2 | F10: 2 | G10: 3 | H10: 나 | I10: 서울대 | J10: 컴퓨터공 | K10: 자연 | L10: =IF(OFFSET(환산공식!$DU$15,$F10,0)=1,"O","X") -> X | M10: =IFERROR(OFFSET(환산공식!DA$15,$F10,0),"") -> 0 | N10: =IFERROR(CONCATENATE(ROUND(OFFSET(환산공식!DB$15,$F10,0),1),"%"),"") | O10: =IFERROR(OFFSET(환산공식!DC$15,$F10,0),"") -> 0 | P10: =IF(E10="","",IF(Q10>R10,"90% 이상",IF(Q10>S10,CONCATENATE(ROUND(((Q10-S10)/(R10-S10))*20+70,0),"%"),IF(Q10>T10,CONCATENATE(ROUND(((Q10-T10)/(S10-T10))*30+40,0),"%"),IF(Q10>U10,CONCATENATE(ROUND(((Q10-U10)/(T10-U10))*30+10,0),"%"),IF(Q10>V10,CONCATENATE(ROUND(((Q10-V10)/(U10-V10))*7+3,0),"%"),"3% 이하")))))) -> 3% 이하 | Q10: =IFERROR(ROUND(OFFSET(환산공식!$EX$15,$F10,0),3),"") -> 0 | R10: =OFFSET('배치점수 계산기'!H$10,$D10,0) -> 407.66 | S10: =OFFSET('배치점수 계산기'!I$10,$D10,0) -> 405.88 | T10: =OFFSET('배치점수 계산기'!J$10,$D10,0) -> 403.46 | U10: =OFFSET('배치점수 계산기'!K$10,$D10,0) -> 400.96 | V10: =OFFSET('배치점수 계산기'!L$10,$D10,0) -> 396.34 | W10: =OFFSET('배치점수 계산기'!M$10,$D10,0) -> 표점 | X10: =OFFSET('배치점수 계산기'!N$10,$D10,0) -> 표점 | Y10: =OFFSET(환산공식!FG$15,$F10,0) -> 0.33 | Z10: =OFFSET(환산공식!FH$15,$F10,0) -> 0.4 | AA10: =OFFSET(환산공식!FI$15,$F10,0) -> 0.27 | AD10: =IF(L10="X",6,IF(Q10>R10,1,IF(Q10>S10,2,IF(Q10>T10,3,IF(Q10>U10,4,IF(Q10>=V10,5,IF(Q10<V10,6,""))))))) -> 6
C11: 나4 | D11: 906 | E11: 2 | F11: 2 | G11: 4 | H11: 나 | I11: 서울대 | J11: 통계 | K11: 자연 | L11: =IF(OFFSET(환산공식!$DU$15,$F11,0)=1,"O","X") -> X | M11: =IFERROR(OFFSET(환산공식!DA$15,$F11,0),"") -> 0 | N11: =IFERROR(CONCATENATE(ROUND(OFFSET(환산공식!DB$15,$F11,0),1),"%"),"") | O11: =IFERROR(OFFSET(환산공식!DC$15,$F11,0),"") -> 0 | P11: =IF(E11="","",IF(Q11>R11,"90% 이상",IF(Q11>S11,CONCATENATE(ROUND(((Q11-S11)/(R11-S11))*20+70,0),"%"),IF(Q11>T11,CONCATENATE(ROUND(((Q11-T11)/(S11-T11))*30+40,0),"%"),IF(Q11>U11,CONCATENATE(ROUND(((Q11-U11)/(T11-U11))*30+10,0),"%"),IF(Q11>V11,CONCATENATE(ROUND(((Q11-V11)/(U11-V11))*7+3,0),"%"),"3% 이하")))))) -> 3% 이하 | Q11: =IFERROR(ROUND(OFFSET(환산공식!$EX$15,$F11,0),3),"") -> 0 | R11: =OFFSET('배치점수 계산기'!H$10,$D11,0) -> 404.44 | S11: =OFFSET('배치점수 계산기'!I$10,$D11,0) -> 403.25 | T11: =OFFSET('배치점수 계산기'!J$10,$D11,0) -> 402.09 | U11: =OFFSET('배치점수 계산기'!K$10,$D11,0) -> 398.86 | V11: =OFFSET('배치점수 계산기'!L$10,$D11,0) -> 397.22 | W11: =OFFSET('배치점수 계산기'!M$10,$D11,0) -> 표점 | X11: =OFFSET('배치점수 계산기'!N$10,$D11,0) -> 표점 | Y11: =OFFSET(환산공식!FG$15,$F11,0) -> 0.33 | Z11: =OFFSET(환산공식!FH$15,$F11,0) -> 0.4 | AA11: =OFFSET(환산공식!FI$15,$F11,0) -> 0.27 | AD11: =IF(L11="X",6,IF(Q11>R11,1,IF(Q11>S11,2,IF(Q11>T11,3,IF(Q11>U11,4,IF(Q11>=V11,5,IF(Q11<V11,6,""))))))) -> 6
C12: 나5 | D12: 907 | E12: 2 | F12: 2 | G12: 5 | H12: 나 | I12: 서울대 | J12: 산업공학 | K12: 자연 | L12: =IF(OFFSET(환산공식!$DU$15,$F12,0)=1,"O","X") -> X | M12: =IFERROR(OFFSET(환산공식!DA$15,$F12,0),"") -> 0 | N12: =IFERROR(CONCATENATE(ROUND(OFFSET(환산공식!DB$15,$F12,0),1),"%"),"") | O12: =IFERROR(OFFSET(환산공식!DC$15,$F12,0),"") -> 0 | P12: =IF(E12="","",IF(Q12>R12,"90% 이상",IF(Q12>S12,CONCATENATE(ROUND(((Q12-S12)/(R12-S12))*20+70,0),"%"),IF(Q12>T12,CONCATENATE(ROUND(((Q12-T12)/(S12-T12))*30+40,0),"%"),IF(Q12>U12,CONCATENATE(ROUND(((Q12-U12)/(T12-U12))*30+10,0),"%"),IF(Q12>V12,CONCATENATE(ROUND(((Q12-V12)/(U12-V12))*7+3,0),"%"),"3% 이하")))))) -> 3% 이하 | Q12: =IFERROR(ROUND(OFFSET(환산공식!$EX$15,$F12,0),3),"") -> 0 | R12: =OFFSET('배치점수 계산기'!H$10,$D12,0) -> 402.09 | S12: =OFFSET('배치점수 계산기'!I$10,$D12,0) -> 401.44 | T12: =OFFSET('배치점수 계산기'!J$10,$D12,0) -> 401.17 | U12: =OFFSET('배치점수 계산기'!K$10,$D12,0) -> 397.6 | V12: =OFFSET('배치점수 계산기'!L$10,$D12,0) -> 394.61 | W12: =OFFSET('배치점수 계산기'!M$10,$D12,0) -> 표점 | X12: =OFFSET('배치점수 계산기'!N$10,$D12,0) -> 표점 | Y12: =OFFSET(환산공식!FG$15,$F12,0) -> 0.33 | Z12: =OFFSET(환산공식!FH$15,$F12,0) -> 0.4 | AA12: =OFFSET(환산공식!FI$15,$F12,0) -> 0.27 | AD12: =IF(L12="X",6,IF(Q12>R12,1,IF(Q12>S12,2,IF(Q12>T12,3,IF(Q12>U12,4,IF(Q12>=V12,5,IF(Q12<V12,6,""))))))) -> 6
